Workbook

Sheet 说明
A1: 运营工作台 · 使用说明
A2: 本工作簿是『模板』。规则源=templates/运营工作台-规格与规则源.md；真实店铺数据请复制为本地工作副本填写，不要提交 git。
B4: ① 第一步 | C4: 复制本模板为你的工作副本（放本地、勿提交 git，含真实店铺数据 + 频繁变动）。在副本里填数据、做运营。
B5: ② 使用流程 | C5: SKU主表 录候选 → 选品打分 排序选出 Top → 选中的进 利润计算 试价（看『保本价/达标价红线』）→ 上架 → 商品四象限分层 回填漏斗数据复盘 → 回 SKU主表 迭代状态。
B6: ③ 改费率/税/阈值 | C6: 只改『参数配置』一处，其余 sheet 自动联动。每个数值旁注『以官方后台为准 + 核对日期』，请按当期后台核对后更新。
B7: ④ 一票否决 | C7: 禁售 / 需资质未备 / IP无授权 / 带球队logo → 选品打分 自动判『淘汰』，不进利润表。SKU主表『禁限售核查』：禁售=红、需资质=黄。
B8: ⑤ 话术/FAQ | C8: 达人邀约话术、客服FAQ 已给马来语/英语对照。不够用时找 AI 现生成马来语版，本地化润色后再贴回。
B9: ⑥ 免责声明 | C9: 所有费率/税/SLA/物流时效均为资料口径，可能过期；上架/定价/承诺前务必以 TikTok Shop 卖家中心·学习中心/Help Center 当期显示为准。
B11: 颜色规范 | C11: 颜色规范（行业惯例）
B12: 蓝色字 | C12: 可编辑输入：你按场景/店铺改的数字（售价、进货价、打分、阈值…）
B13: 黑色字 | C13: 公式/计算结果：请勿手动覆盖，会断开联动
B14: 绿色字 | C14: 跨表引用：从其它 sheet（多为 SKU主表 / 参数配置）自动带出
B15: 黄色底 | C15: 关键假设/费率：需重点核对的官方口径数值（参数配置里）
B16: 红色 | C16: 禁售 / 售价低于保本价(亏损) / 一票否决 等硬警示
... B26: 客服FAQ+自动回复 | C26: 欢迎语 + 8 订单状态自动回复 + 常见问题，中英(含马来)对照；含时效红线。

Sheet 参数配置
A1: 参数配置 · 全局变量（费率 / 汇率 / 税 / 阈值集中管理）
A2: ⚠️ 所有费率/税/SLA 以 TikTok Shop 官方后台当期为准；改动只改本表 B 列，其余 sheet 自动联动。默认值为资料口径示例，使用前务必核对并填核对日期。
A3: 参数 | B3: 默认值 | C3: 单位 | D3: 说明（口径 / 核对日期）
A4: 一、费率 · 税 · 物流（⚠️ 以官方后台为准 + 核对日期）
A5: 汇率 MYR→RMB | B5: 1.6997 | C5: RMB/MYR | D5: 资料定价口径；实际以当下实时汇率为准。以官方后台为准 ｜ 核对日期：____
A6: 类目佣金率（默认，可被利润表逐行覆盖） | B6: 0.0846 | C6: % | D6: 默认取马来资料示例 8.46%（属类目佣金，落在 非Mall 7–11% / Mall 10–15% 区间，含SST；2025-09-13 起上调，BXP 超补商家不受影响）。按你的类目/是否 Mall 改为后台实际费率。以官方后台为准 ｜ 核对日期：____
A7: 交易手续费 | B7: 0.0378 | C7: % | D7: 含 8% SST，2024-09-05 起上调。以官方后台为准 ｜ 核对日期：____
A8: 平台支持费 | B8: 0.54 | C8: RM/单 | D8: RM0.50 + 8% SST = RM0.54，2026-02-15 起。以官方后台为准 ｜ 核对日期：____
A9: 达人佣金率 | B9: 0.05 | C9: % | D9: 视频带货默认 5%；主推/直播款 8–15%。签约前以实际谈判为准。
A10: LVG 税率 | B10: 0.1 | C10: % | D10: 低价值进口税；适用售价 ≤ 下方上限。平台代收，此处算给卖家看真实税负。以官方后台为准 ｜ 核对日期：____
A11: LVG 适用售价上限 | B11: 500 | C11: MYR | D11: 售价 ≤ RM500 适用 LVG；> RM500 走常规进口（利润表自动提示，请自行核算进口税）。以官方后台为准 ｜ 核对日期：____
A12: 二、利润目标与预留（自行设定）
A13: 目标利润率 | B13: 0.2 | C13: % | D13: 自行设定；用于反解『达标价红线』（达到此利润率所需的最低售价）。
A14: 退款损耗预留 % | B14: 0.03 | C14: % | D14: 自行设定；马来退货率较低，按本店实际退款率预留。
A15: 广告预留 % | B15: 0.05 | C15: % | D15: 自行设定；为投流/加热预留的成本占比。
A16: 三、选品 · 四象限阈值（自行设定）
A17: 选品-优先上架 Top N | B17: 10 | C17: 个 | D17: 加权总分排名前 N 名判『⭐优先上架 Top N』。
A18: 选品-观察线（加权总分 1–5） | B18: 3.5 | C18: 分 | D18: 加权总分 ≥ 此值但未进 TopN → 判『观察跟进』，否则『暂缓』。
A19: 四象限-曝光阈值（流量轴分界） | B19: 1000 | C19: 次/人 | D19: 曝光 ≥ 此值判『高流量』。按本店数据分布调整。
A20: 四象限-成交率阈值（转化轴分界） | B20: 0.08 | C20: % | D20: 成交率(=成交/加购) ≥ 此值判『高转化』。按类目基准调整。
A21: 四象限-退款率预警线 | B21: 0.08 | C21: % | D21: 退款率 > 此值 → 四象限表标『⚠️退款率偏高』（选品红线信号，多为尺码/质量）。

Sheet SKU主表
A1: SKU 主表 · 候选商品台账（贯穿全表）
A2: 贯穿全表的唯一商品来源。其它 sheet 用『编号』回查本表。『禁限售核查』=禁售→红(一票否决)、需资质→黄(未备齐前不进利润表)。前 4 行为示例，可删。
A3: 编号 | B3: 品名 | C3: 类目 | D3: 货源链接(1688/PDD) | E3: 进货价RMB | F3: 重量g | G3: 尺寸 | H3: 清真合规 | I3: 禁限售核查 | J3: 532分类 | K3: 状态 | L3: 上架日期 | M3: 备注
A4: TKMY-001 | B4: 印花头巾 Hijab Bawal Printed | C4: 穆斯林时尚/配饰 | D4: 1688：示例链接 | E4: 7.5 | F4: 60 | G4: 1.8m×1.8m | H4: 是 | I4: 通过 | J4: 基础 | K4: 候选 | M4: 斋月/开斋节前后高峰；轻小件扛运费
A5: TKMY-002 | B5: 折叠除湿盒 Kotak Penyahlembap | C5: 居家日用 | D5: 1688：示例链接 | E5: 12 | F5: 150 | G5: 12×8×8cm | H5: NA | I5: 通过 | J5: 微创新 | K5: 候选 | M5: 雨季防潮刚需；不可带宗教关键词
A6: TKMY-003 | B6: 矫正近视框架眼镜 | C6: 眼镜 | D6: 1688：示例链接 | E6: 20 | F6: 80 | G6: 标准 | H6: NA | I6: 禁售 | J6: 趋势 | K6: 候选 | M6: ⚠马来禁售矫正型眼镜(近视/远视)→一票否决
A7: TKMY-004 | B7: 儿童保湿面霜 | C7: 美妆个护/母婴 | D7: 1688：示例链接 | E7: 10 | F7: 100 | G7: 50g/瓶 | H7: 是 | I7: 需资质 | J7: 基础 | K7: 候选 | M7: 健康个护/母婴属限售，需资质未备→一票否决

Sheet 选品打分
A1: 选品打分 · 7 维度加权排序
A2: 打分 1–5（5最好）。权重在第 3 行可调、合计应=100%。加权总分降序→排名前 Top N 判优先上架。一票否决(禁售/需资质/IP无授权/带球队logo)直接淘汰、不进利润表。Top N/观察线见『参数配置』。
F3: 权重(可调)→ | G3: 0.2 | H3: 0.2 | I3: 0.15 | J3: 0.15 | K3: 0.1 | L3: 0.1 | M3: 0.1 | N3: =SUM(G3:M3) -> 1
A4: 编号 | B4: 品名 | C4: 禁限售 | D4: IP无授权 | E4: 带球队logo | F4: 一票否决 | G4: 客单价/利润空间 | H4: 扛运费能力(轻小件优先) | I4: 需求热度(数据罗盘) | J4: 竞争度(蓝海高分) | K4: 退货风险(低风险高分) | L4: 趋势/季节契合(斋月等) | M4: 清真合规契合 | N4: 加权总分 | O4: 排名 | P4: 建议
A5: TKMY-001 | B5: =IFERROR(VLOOKUP($A5,SKU主表!$A:$M,2,0),"") -> 印花头巾 Hijab Bawal Printed | C5: =IFERROR(VLOOKUP($A5,SKU主表!$A:$M,9,0),"") -> 通过 | D5: 否 | E5: 否 | F5: =IF($A5="","",IF(OR($C5="禁售",$C5="需资质",$D5="是",$E5="是"),"是","否")) -> 否 | G5: 3 | H5: 5 | I5: 4 | J5: 3 | K5: 4 | L5: 5 | M5: 5 | N5: =IF($A5="","",IF($F5="是",0,SUMPRODUCT($G5:$M5,$G$3:$M$3))) -> 4.05 | O5: =IF(OR($A5="",$N5=""),"",RANK($N5,$N$5:$N$34,0)) -> 1 | P5: =IF($A5="","",IF($F5="是","⛔淘汰(一票否决)",IF($O5<=参数配置!$B$17,"⭐优先上架Top N",IF($N5>=参数配置!$B$18,"观察跟进","暂缓/优化后再评")))) -> ⭐优先上架Top N
A6: TKMY-002 | B6: =IFERROR(VLOOKUP($A6,SKU主表!$A:$M,2,0),"") -> 折叠除湿盒 Kotak Penyahlembap | C6: =IFERROR(VLOOKUP($A6,SKU主表!$A:$M,9,0),"") -> 通过 | D6: 否 | E6: 否 | F6: =IF($A6="","",IF(OR($C6="禁售",$C6="需资质",$D6="是",$E6="是"),"是","否")) -> 否 | G6: 3 | H6: 4 | I6: 4 | J6: 4 | K6: 4 | L6: 4 | M6: 3 | N6: =IF($A6="","",IF($F6="是",0,SUMPRODUCT($G6:$M6,$G$3:$M$3))) -> 3.7 | O6: =IF(OR($A6="",$N6=""),"",RANK($N6,$N$5:$N$34,0)) -> 2 | P6: =IF($A6="","",IF($F6="是","⛔淘汰(一票否决)",IF($O6<=参数配置!$B$17,"⭐优先上架Top N",IF($N6>=参数配置!$B$18,"观察跟进","暂缓/优化后再评")))) -> ⭐优先上架Top N
A7: TKMY-003 | B7: =IFERROR(VLOOKUP($A7,SKU主表!$A:$M,2,0),"") -> 矫正近视框架眼镜 | C7: =IFERROR(VLOOKUP($A7,SKU主表!$A:$M,9,0),"") -> 禁售 | D7: 否 | E7: 否 | F7: =IF($A7="","",IF(OR($C7="禁售",$C7="需资质",$D7="是",$E7="是"),"是","否")) -> 是 | N7: =IF($A7="","",IF($F7="是",0,SUMPRODUCT($G7:$M7,$G$3:$M$3))) -> 0 | O7: =IF(OR($A7="",$N7=""),"",RANK($N7,$N$5:$N$34,0)) -> 3 | P7: =IF($A7="","",IF($F7="是","⛔淘汰(一票否决)",IF($O7<=参数配置!$B$17,"⭐优先上架Top N",IF($N7>=参数配置!$B$18,"观察跟进","暂缓/优化后再评")))) -> ⛔淘汰(一票否决)
A8: TKMY-004 | B8: =IFERROR(VLOOKUP($A8,SKU主表!$A:$M,2,0),"") -> 儿童保湿面霜 | C8: =IFERROR(VLOOKUP($A8,SKU主表!$A:$M,9,0),"") -> 需资质 | D8: 否 | E8: 否 | F8: =IF($A8="","",IF(OR($C8="禁售",$C8="需资质",$D8="是",$E8="是"),"是","否")) -> 是 | N8: =IF($A8="","",IF($F8="是",0,SUMPRODUCT($G8:$M8,$G$3:$M$3))) -> 0 | O8: =IF(OR($A8="",$N8=""),"",RANK($N8,$N$5:$N$34,0)) -> 3 | P8: =IF($A8="","",IF($F8="是","⛔淘汰(一票否决)",IF($O8<=参数配置!$B$17,"⭐优先上架Top N",IF($N8>=参数配置!$B$18,"观察跟进","暂缓/优化后再评")))) -> ⛔淘汰(一票否决)
B9: =IFERROR(VLOOKUP($A9,SKU主表!$A:$M,2,0),"") | C9: =IFERROR(VLOOKUP($A9,SKU主表!$A:$M,9,0),"") | F9: =IF($A9="","",IF(OR($C9="禁售",$C9="需资质",$D9="是",$E9="是"),"是","否")) | N9: =IF($A9="","",IF($F9="是",0,SUMPRODUCT($G9:$M9,$G$3:$M$3))) | O9: =IF(OR($A9="",$N9=""),"",RANK($N9,$N$5:$N$34,0)) | P9: =IF($A9="","",IF($F9="是","⛔淘汰(一票否决)",IF($O9<=参数配置!$B$17,"⭐优先上架Top N",IF($N9>=参数配置!$B$18,"观察跟进","暂缓/优化后再评"))))
B10: =IFERROR(VLOOKUP($A10,SKU主表!$A:$M,2,0),"") | C10: =IFERROR(VLOOKUP($A10,SKU主表!$A:$M,9,0),"") | F10: =IF($A10="","",IF(OR($C10="禁售",$C10="需资质",$D10="是",$E10="是"),"是","否")) | N10: =IF($A10="","",IF($F10="是",0,SUMPRODUCT($G10:$M10,$G$3:$M$3))) | O10: =IF(OR($A10="",$N10=""),"",RANK($N10,$N$5:$N$34,0)) | P10: =IF($A10="","",IF($F10="是","⛔淘汰(一票否决)",IF($O10<=参数配置!$B$17,"⭐优先上架Top N",IF($N10>=参数配置!$B$18,"观察跟进","暂缓/优化后再评"))))
B11: =IFERROR(VLOOKUP($A11,SKU主表!$A:$M,2,0),"") | C11: =IFERROR(VLOOKUP($A11,SKU主表!$A:$M,9,0),"") | F11: =IF($A11="","",IF(OR($C11="禁售",$C11="需资质",$D11="是",$E11="是"),"是","否")) | N11: =IF($A11="","",IF($F11="是",0,SUMPRODUCT($G11:$M11,$G$3:$M$3))) | O11: =IF(OR($A11="",$N11=""),"",RANK($N11,$N$5:$N$34,0)) | P11: =IF($A11="","",IF($F11="是","⛔淘汰(一票否决)",IF($O11<=参数配置!$B$17,"⭐优先上架Top N",IF($N11>=参数配置!$B$18,"观察跟进","暂缓/优化后再评"))))
B12: =IFERROR(VLOOKUP($A12,SKU主表!$A:$M,2,0),"") | C12: =IFERROR(VLOOKUP($A12,SKU主表!$A:$M,9,0),"") | F12: =IF($A12="","",IF(OR($C12="禁售",$C12="需资质",$D12="是",$E12="是"),"是","否")) | N12: =IF($A12="","",IF($F12="是",0,SUMPRODUCT($G12:$M12,$G$3:$M$3))) | O12: =IF(OR($A12="",$N12=""),"",RANK($N12,$N$5:$N$34,0)) | P12: =IF($A12="","",IF($F12="是","⛔淘汰(一票否决)",IF($O12<=参数配置!$B$17,"⭐优先上架Top N",IF($N12>=参数配置!$B$18,"观察跟进","暂缓/优化后再评"))))
B13: =IFERROR(VLOOKUP($A13,SKU主表!$A:$M,2,0),"") | C13: =IFERROR(VLOOKUP($A13,SKU主表!$A:$M,9,0),"") | F13: =IF($A13="","",IF(OR($C13="禁售",$C13="需资质",$D13="是",$E13="是"),"是","否")) | N13: =IF($A13="","",IF($F13="是",0,SUMPRODUCT($G13:$M13,$G$3:$M$3))) | O13: =IF(OR($A13="",$N13=""),"",RANK($N13,$N$5:$N$34,0)) | P13: =IF($A13="","",IF($F13="是","⛔淘汰(一票否决)",IF($O13<=参数配置!$B$17,"⭐优先上架Top N",IF($N13>=参数配置!$B$18,"观察跟进","暂缓/优化后再评"))))
B14: =IFERROR(VLOOKUP($A14,SKU主表!$A:$M,2,0),"") | C14: =IFERROR(VLOOKUP($A14,SKU主表!$A:$M,9,0),"") | F14: =IF($A14="","",IF(OR($C14="禁售",$C14="需资质",$D14="是",$E14="是"),"是","否")) | N14: =IF($A14="","",IF($F14="是",0,SUMPRODUCT($G14:$M14,$G$3:$M$3))) | O14: =IF(OR($A14="",$N14=""),"",RANK($N14,$N$5:$N$34,0)) | P14: =IF($A14="","",IF($F14="是","⛔淘汰(一票否决)",IF($O14<=参数配置!$B$17,"⭐优先上架Top N",IF($N14>=参数配置!$B$18,"观察跟进","暂缓/优化后再评"))))
B15: =IFERROR(VLOOKUP($A15,SKU主表!$A:$M,2,0),"") | C15: =IFERROR(VLOOKUP($A15,SKU主表!$A:$M,9,0),"") | F15: =IF($A15="","",IF(OR($C15="禁售",$C15="需资质",$D15="是",$E15="是"),"是","否")) | N15: =IF($A15="","",IF($F15="是",0,SUMPRODUCT($G15:$M15,$G$3:$M$3))) | O15: =IF(OR($A15="",$N15=""),"",RANK($N15,$N$5:$N$34,0)) | P15: =IF($A15="","",IF($F15="是","⛔淘汰(一票否决)",IF($O15<=参数配置!$B$17,"⭐优先上架Top N",IF($N15>=参数配置!$B$18,"观察跟进","暂缓/优化后再评"))))
B16: =IFERROR(VLOOKUP($A16,SKU主表!$A:$M,2,0),"") | C16: =IFERROR(VLOOKUP($A16,SKU主表!$A:$M,9,0),"") | F16: =IF($A16="","",IF(OR($C16="禁售",$C16="需资质",$D16="是",$E16="是"),"是","否")) | N16: =IF($A16="","",IF($F16="是",0,SUMPRODUCT($G16:$M16,$G$3:$M$3))) | O16: =IF(OR($A16="",$N16=""),"",RANK($N16,$N$5:$N$34,0)) | P16: =IF($A16="","",IF($F16="是","⛔淘汰(一票否决)",IF($O16<=参数配置!$B$17,"⭐优先上架Top N",IF($N16>=参数配置!$B$18,"观察跟进","暂缓/优化后再评"))))
B17: =IFERROR(VLOOKUP($A17,SKU主表!$A:$M,2,0),"") | C17: =IFERROR(VLOOKUP($A17,SKU主表!$A:$M,9,0),"") | F17: =IF($A17="","",IF(OR($C17="禁售",$C17="需资质",$D17="是",$E17="是"),"是","否")) | N17: =IF($A17="","",IF($F17="是",0,SUMPRODUCT($G17:$M17,$G$3:$M$3))) | O17: =IF(OR($A17="",$N17=""),"",RANK($N17,$N$5:$N$34,0)) | P17: =IF($A17="","",IF($F17="是","⛔淘汰(一票否决)",IF($O17<=参数配置!$B$17,"⭐优先上架Top N",IF($N17>=参数配置!$B$18,"观察跟进","暂缓/优化后再评"))))
B18: =IFERROR(VLOOKUP($A18,SKU主表!$A:$M,2,0),"") | C18: =IFERROR(VLOOKUP($A18,SKU主表!$A:$M,9,0),"") | F18: =IF($A18="","",IF(OR($C18="禁售",$C18="需资质",$D18="是",$E18="是"),"是","否")) | N18: =IF($A18="","",IF($F18="是",0,SUMPRODUCT($G18:$M18,$G$3:$M$3))) | O18: =IF(OR($A18="",$N18=""),"",RANK($N18,$N$5:$N$34,0)) | P18: =IF($A18="","",IF($F18="是","⛔淘汰(一票否决)",IF($O18<=参数配置!$B$17,"⭐优先上架Top N",IF($N18>=参数配置!$B$18,"观察跟进","暂缓/优化后再评"))))
B19: =IFERROR(VLOOKUP($A19,SKU主表!$A:$M,2,0),"") | C19: =IFERROR(VLOOKUP($A19,SKU主表!$A:$M,9,0),"") | F19: =IF($A19="","",IF(OR($C19="禁售",$C19="需资质",$D19="是",$E19="是"),"是","否")) | N19: =IF($A19="","",IF($F19="是",0,SUMPRODUCT($G19:$M19,$G$3:$M$3))) | O19: =IF(OR($A19="",$N19=""),"",RANK($N19,$N$5:$N$34,0)) | P19: =IF($A19="","",IF($F19="是","⛔淘汰(一票否决)",IF($O19<=参数配置!$B$17,"⭐优先上架Top N",IF($N19>=参数配置!$B$18,"观察跟进","暂缓/优化后再评"))))
B20: =IFERROR(VLOOKUP($A20,SKU主表!$A:$M,2,0),"") | C20: =IFERROR(VLOOKUP($A20,SKU主表!$A:$M,9,0),"") | F20: =IF($A20="","",IF(OR($C20="禁售",$C20="需资质",$D20="是",$E20="是"),"是","否")) | N20: =IF($A20="","",IF($F20="是",0,SUMPRODUCT($G20:$M20,$G$3:$M$3))) | O20: =IF(OR($A20="",$N20=""),"",RANK($N20,$N$5:$N$34,0)) | P20: =IF($A20="","",IF($F20="是","⛔淘汰(一票否决)",IF($O20<=参数配置!$B$17,"⭐优先上架Top N",IF($N20>=参数配置!$B$18,"观察跟进","暂缓/优化后再评"))))
... B34: =IFERROR(VLOOKUP($A34,SKU主表!$A:$M,2,0),"") | C34: =IFERROR(VLOOKUP($A34,SKU主表!$A:$M,9,0),"") | F34: =IF($A34="","",IF(OR($C34="禁售",$C34="需资质",$D34="是",$E34="是"),"是","否")) | N34: =IF($A34="","",IF($F34="是",0,SUMPRODUCT($G34:$M34,$G$3:$M$3))) | O34: =IF(OR($A34="",$N34=""),"",RANK($N34,$N$5:$N$34,0)) | P34: =IF($A34="","",IF($F34="是","⛔淘汰(一票否决)",IF($O34<=参数配置!$B$17,"⭐优先上架Top N",IF($N34>=参数配置!$B$18,"观察跟进","暂缓/优化后再评"))))

Sheet 利润计算
A1: 利润计算 · 多档售价试算 + 反解最低成交价红线
A2: 蓝色列为输入（编号→自动带品名/进货价/禁限售）。费率/税/汇率全部引用『参数配置』。售价 < 保本价→标红(亏损)；保本价≤售价<达标价→标黄(未达目标利润率)。禁售/需资质的SKU状态列会警示『不应进入利润表』。
A3: 编号 | B3: 品名 | C3: 禁限售 | D3: 进货价RMB | E3: 售价MYR | F3: 跨境物流MYR | G3: 活动让利% | H3: 类目佣金率(本品) | I3: 进货成本MYR | J3: 佣金 | K3: 交易手续费 | L3: 平台支持费 | M3: 达人佣金 | N3: LVG税 | O3: 活动让利 | P3: 退款损耗 | Q3: 广告预留 | R3: 总成本MYR | S3: 利润MYR | T3: 利润率 | U3: 利润RMB | V3: 贡献率m | W3: 固定成本MYR | X3: 保本价(红线·亏损线) | Y3: 达标价(目标利润率) | Z3: 状态提示
A4: TKMY-001 | B4: =IFERROR(VLOOKUP($A4,SKU主表!$A:$M,2,0),"") -> 印花头巾 Hijab Bawal Printed | C4: =IFERROR(VLOOKUP($A4,SKU主表!$A:$M,9,0),"") -> 通过 | D4: =IFERROR(VLOOKUP($A4,SKU主表!$A:$M,5,0),"") -> 7.5 | E4: 30 | F4: 4 | G4: 0.1 | H4: =参数配置!$B$6 -> 0.0846 | I4: =IF($D4="","",$D4/参数配置!$B$5) -> 4.4125434 | J4: =IF($E4="","",$E4*$H4) -> 2.538 | K4: =IF($E4="","",$E4*参数配置!$B$7) -> 1.134 | L4: =IF($E4="","",参数配置!$B$8) -> 0.54 | M4: =IF($E4="","",$E4*参数配置!$B$9) -> 1.5 | N4: =IF($E4="","",IF($E4<=参数配置!$B$11,$E4*参数配置!$B$10,0)) -> 3 | O4: =IF($E4="","",$E4*$G4) -> 3 | P4: =IF($E4="","",$E4*参数配置!$B$14) -> 0.9 | Q4: =IF($E4="","",$E4*参数配置!$B$15) -> 1.5 | R4: =IF($E4="","",$I4+$F4+$J4+$K4+$L4+$M4+$N4+$O4+$P4+$Q4) -> 22.524543 | S4: =IF($E4="","",$E4-$R4) -> 7.4754566 | T4: =IF(OR($E4="",$E4=0),"",$S4/$E4) -> 0.24918189 | U4: =IF($E4="","",$S4*参数配置!$B$5) -> 12.706034 | V4: =IF($E4="","",1-$H4-参数配置!$B$7-参数配置!$B$9-$G4-参数配置!$B$14-参数配置!$B$15-IF($E4<=参数配置!$B$11,参数配置!$B$10,0)) -> 0.5476 | W4: =IF($E4="","",$I4+$F4+$L4) -> 8.9525434 | X4: =IF($E4="","",IF($V4>0,$W4/$V4,"")) -> 16.348691 | Y4: =IF($E4="","",IF(($V4-参数配置!$B$13)>0,$W4/($V4-参数配置!$B$13),"")) -> 25.755303 | Z4: =IF($E4="","",IF(OR($C4="禁售",$C4="需资质"),"⛔"&$C4&"·不应进入利润表",IF($V4<=0,"❗贡献率≤0·任何价都亏损",IF($E4<$X4,"⛔低于保本价·亏损",IF($Y4="","⚠️目标不可达·需降本",IF($E4<$Y4,"⚠️低于红线·未达目标利润率","✅达目标利润率")))))) -> ✅达目标利润率
A5: TKMY-001 | B5: =IFERROR(VLOOKUP($A5,SKU主表!$A:$M,2,0),"") -> 印花头巾 Hijab Bawal Printed | C5: =IFERROR(VLOOKUP($A5,SKU主表!$A:$M,9,0),"") -> 通过 | D5: =IFERROR(VLOOKUP($A5,SKU主表!$A:$M,5,0),"") -> 7.5 | E5: 15 | F5: 4 | G5: 0.1 | H5: =参数配置!$B$6 -> 0.0846 | I5: =IF($D5="","",$D5/参数配置!$B$5) -> 4.4125434 | J5: =IF($E5="","",$E5*$H5) -> 1.269 | K5: =IF($E5="","",$E5*参数配置!$B$7) -> 0.567 | L5: =IF($E5="","",参数配置!$B$8) -> 0.54 | M5: =IF($E5="","",$E5*参数配置!$B$9) -> 0.75 | N5: =IF($E5="","",IF($E5<=参数配置!$B$11,$E5*参数配置!$B$10,0)) -> 1.5 | O5: =IF($E5="","",$E5*$G5) -> 1.5 | P5: =IF($E5="","",$E5*参数配置!$B$14) -> 0.45 | Q5: =IF($E5="","",$E5*参数配置!$B$15) -> 0.75 | R5: =IF($E5="","",$I5+$F5+$J5+$K5+$L5+$M5+$N5+$O5+$P5+$Q5) -> 15.738543 | S5: =IF($E5="","",$E5-$R5) -> -0.73854339 | T5: =IF(OR($E5="",$E5=0),"",$S5/$E5) -> -0.049236226 | U5: =IF($E5="","",$S5*参数配置!$B$5) -> -1.2553022 | V5: =IF($E5="","",1-$H5-参数配置!$B$7-参数配置!$B$9-$G5-参数配置!$B$14-参数配置!$B$15-IF($E5<=参数配置!$B$11,参数配置!$B$10,0)) -> 0.5476 | W5: =IF($E5="","",$I5+$F5+$L5) -> 8.9525434 | X5: =IF($E5="","",IF($V5>0,$W5/$V5,"")) -> 16.348691 | Y5: =IF($E5="","",IF(($V5-参数配置!$B$13)>0,$W5/($V5-参数配置!$B$13),"")) -> 25.755303 | Z5: =IF($E5="","",IF(OR($C5="禁售",$C5="需资质"),"⛔"&$C5&"·不应进入利润表",IF($V5<=0,"❗贡献率≤0·任何价都亏损",IF($E5<$X5,"⛔低于保本价·亏损",IF($Y5="","⚠️目标不可达·需降本",IF($E5<$Y5,"⚠️低于红线·未达目标利润率","✅达目标利润率")))))) -> ⛔低于保本价·亏损
A6: TKMY-001 | B6: =IFERROR(VLOOKUP($A6,SKU主表!$A:$M,2,0),"") -> 印花头巾 Hijab Bawal Printed | C6: =IFERROR(VLOOKUP($A6,SKU主表!$A:$M,9,0),"") -> 通过 | D6: =IFERROR(VLOOKUP($A6,SKU主表!$A:$M,5,0),"") -> 7.5 | E6: 20 | F6: 4 | G6: 0.1 | H6: =参数配置!$B$6 -> 0.0846 | I6: =IF($D6="","",$D6/参数配置!$B$5) -> 4.4125434 | J6: =IF($E6="","",$E6*$H6) -> 1.692 | K6: =IF($E6="","",$E6*参数配置!$B$7) -> 0.756 | L6: =IF($E6="","",参数配置!$B$8) -> 0.54 | M6: =IF($E6="","",$E6*参数配置!$B$9) -> 1 | N6: =IF($E6="","",IF($E6<=参数配置!$B$11,$E6*参数配置!$B$10,0)) -> 2 | O6: =IF($E6="","",$E6*$G6) -> 2 | P6: =IF($E6="","",$E6*参数配置!$B$14) -> 0.6 | Q6: =IF($E6="","",$E6*参数配置!$B$15) -> 1 | R6: =IF($E6="","",$I6+$F6+$J6+$K6+$L6+$M6+$N6+$O6+$P6+$Q6) -> 18.000543 | S6: =IF($E6="","",$E6-$R6) -> 1.9994566 | T6: =IF(OR($E6="",$E6=0),"",$S6/$E6) -> 0.09997283 | U6: =IF($E6="","",$S6*参数配置!$B$5) -> 3.3984764 | V6: =IF($E6="","",1-$H6-参数配置!$B$7-参数配置!$B$9-$G6-参数配置!$B$14-参数配置!$B$15-IF($E6<=参数配置!$B$11,参数配置!$B$10,0)) -> 0.5476 | W6: =IF($E6="","",$I6+$F6+$L6) -> 8.9525434 | X6: =IF($E6="","",IF($V6>0,$W6/$V6,"")) -> 16.348691 | Y6: =IF($E6="","",IF(($V6-参数配置!$B$13)>0,$W6/($V6-参数配置!$B$13),"")) -> 25.755303 | Z6: =IF($E6="","",IF(OR($C6="禁售",$C6="需资质"),"⛔"&$C6&"·不应进入利润表",IF($V6<=0,"❗贡献率≤0·任何价都亏损",IF($E6<$X6,"⛔低于保本价·亏损",IF($Y6="","⚠️目标不可达·需降本",IF($E6<$Y6,"⚠️低于红线·未达目标利润率","✅达目标利润率")))))) -> ⚠️低于红线·未达目标利润率
A7: TKMY-002 | B7: =IFERROR(VLOOKUP($A7,SKU主表!$A:$M,2,0),"") -> 折叠除湿盒 Kotak Penyahlembap | C7: =IFERROR(VLOOKUP($A7,SKU主表!$A:$M,9,0),"") -> 通过 | D7: =IFERROR(VLOOKUP($A7,SKU主表!$A:$M,5,0),"") -> 12 | E7: 35 | F7: 6 | G7: 0.1 | H7: =参数配置!$B$6 -> 0.0846 | I7: =IF($D7="","",$D7/参数配置!$B$5) -> 7.0600694 | J7: =IF($E7="","",$E7*$H7) -> 2.961 | K7: =IF($E7="","",$E7*参数配置!$B$7) -> 1.323 | L7: =IF($E7="","",参数配置!$B$8) -> 0.54 | M7: =IF($E7="","",$E7*参数配置!$B$9) -> 1.75 | N7: =IF($E7="","",IF($E7<=参数配置!$B$11,$E7*参数配置!$B$10,0)) -> 3.5 | O7: =IF($E7="","",$E7*$G7) -> 3.5 | P7: =IF($E7="","",$E7*参数配置!$B$14) -> 1.05 | Q7: =IF($E7="","",$E7*参数配置!$B$15) -> 1.75 | R7: =IF($E7="","",$I7+$F7+$J7+$K7+$L7+$M7+$N7+$O7+$P7+$Q7) -> 29.434069 | S7: =IF($E7="","",$E7-$R7) -> 5.5659306 | T7: =IF(OR($E7="",$E7=0),"",$S7/$E7) -> 0.15902659 | U7: =IF($E7="","",$S7*参数配置!$B$5) -> 9.4604122 | V7: =IF($E7="","",1-$H7-参数配置!$B$7-参数配置!$B$9-$G7-参数配置!$B$14-参数配置!$B$15-IF($E7<=参数配置!$B$11,参数配置!$B$10,0)) -> 0.5476 | W7: =IF($E7="","",$I7+$F7+$L7) -> 13.600069 | X7: =IF($E7="","",IF($V7>0,$W7/$V7,"")) -> 24.835773 | Y7: =IF($E7="","",IF(($V7-参数配置!$B$13)>0,$W7/($V7-参数配置!$B$13),"")) -> 39.125631 | Z7: =IF($E7="","",IF(OR($C7="禁售",$C7="需资质"),"⛔"&$C7&"·不应进入利润表",IF($V7<=0,"❗贡献率≤0·任何价都亏损",IF($E7<$X7,"⛔低于保本价·亏损",IF($Y7="","⚠️目标不可达·需降本",IF($E7<$Y7,"⚠️低于红线·未达目标利润率","✅达目标利润率")))))) -> ⚠️低于红线·未达目标利润率
A8: TKMY-003 | B8: =IFERROR(VLOOKUP($A8,SKU主表!$A:$M,2,0),"") -> 矫正近视框架眼镜 | C8: =IFERROR(VLOOKUP($A8,SKU主表!$A:$M,9,0),"") -> 禁售 | D8: =IFERROR(VLOOKUP($A8,SKU主表!$A:$M,5,0),"") -> 20 | E8: 30 | F8: 5 | G8: 0.1 | H8: =参数配置!$B$6 -> 0.0846 | I8: =IF($D8="","",$D8/参数配置!$B$5) -> 11.766782 | J8: =IF($E8="","",$E8*$H8) -> 2.538 | K8: =IF($E8="","",$E8*参数配置!$B$7) -> 1.134 | L8: =IF($E8="","",参数配置!$B$8) -> 0.54 | M8: =IF($E8="","",$E8*参数配置!$B$9) -> 1.5 | N8: =IF($E8="","",IF($E8<=参数配置!$B$11,$E8*参数配置!$B$10,0)) -> 3 | O8: =IF($E8="","",$E8*$G8) -> 3 | P8: =IF($E8="","",$E8*参数配置!$B$14) -> 0.9 | Q8: =IF($E8="","",$E8*参数配置!$B$15) -> 1.5 | R8: =IF($E8="","",$I8+$F8+$J8+$K8+$L8+$M8+$N8+$O8+$P8+$Q8) -> 30.878782 | S8: =IF($E8="","",$E8-$R8) -> -0.87878237 | T8: =IF(OR($E8="",$E8=0),"",$S8/$E8) -> -0.029292746 | U8: =IF($E8="","",$S8*参数配置!$B$5) -> -1.4936664 | V8: =IF($E8="","",1-$H8-参数配置!$B$7-参数配置!$B$9-$G8-参数配置!$B$14-参数配置!$B$15-IF($E8<=参数配置!$B$11,参数配置!$B$10,0)) -> 0.5476 | W8: =IF($E8="","",$I8+$F8+$L8) -> 17.306782 | X8: =IF($E8="","",IF($V8>0,$W8/$V8,"")) -> 31.604789 | Y8: =IF($E8="","",IF(($V8-参数配置!$B$13)>0,$W8/($V8-参数配置!$B$13),"")) -> 49.789362 | Z8: =IF($E8="","",IF(OR($C8="禁售",$C8="需资质"),"⛔"&$C8&"·不应进入利润表",IF($V8<=0,"❗贡献率≤0·任何价都亏损",IF($E8<$X8,"⛔低于保本价·亏损",IF($Y8="","⚠️目标不可达·需降本",IF($E8<$Y8,"⚠️低于红线·未达目标利润率","✅达目标利润率")))))) -> ⛔禁售·不应进入利润表
B9: =IFERROR(VLOOKUP($A9,SKU主表!$A:$M,2,0),"") | C9: =IFERROR(VLOOKUP($A9,SKU主表!$A:$M,9,0),"") | D9: =IFERROR(VLOOKUP($A9,SKU主表!$A:$M,5,0),"") | H9: =参数配置!$B$6 -> 0.0846 | I9: =IF($D9="","",$D9/参数配置!$B$5) | J9: =IF($E9="","",$E9*$H9) | K9: =IF($E9="","",$E9*参数配置!$B$7) | L9: =IF($E9="","",参数配置!$B$8) | M9: =IF($E9="","",$E9*参数配置!$B$9) | N9: =IF($E9="","",IF($E9<=参数配置!$B$11,$E9*参数配置!$B$10,0)) | O9: =IF($E9="","",$E9*$G9) | P9: =IF($E9="","",$E9*参数配置!$B$14) | Q9: =IF($E9="","",$E9*参数配置!$B$15) | R9: =IF($E9="","",$I9+$F9+$J9+$K9+$L9+$M9+$N9+$O9+$P9+$Q9) | S9: =IF($E9="","",$E9-$R9) | T9: =IF(OR($E9="",$E9=0),"",$S9/$E9) | U9: =IF($E9="","",$S9*参数配置!$B$5) | V9: =IF($E9="","",1-$H9-参数配置!$B$7-参数配置!$B$9-$G9-参数配置!$B$14-参数配置!$B$15-IF($E9<=参数配置!$B$11,参数配置!$B$10,0)) | W9: =IF($E9="","",$I9+$F9+$L9) | X9: =IF($E9="","",IF($V9>0,$W9/$V9,"")) | Y9: =IF($E9="","",IF(($V9-参数配置!$B$13)>0,$W9/($V9-参数配置!$B$13),"")) | Z9: =IF($E9="","",IF(OR($C9="禁售",$C9="需资质"),"⛔"&$C9&"·不应进入利润表",IF($V9<=0,"❗贡献率≤0·任何价都亏损",IF($E9<$X9,"⛔低于保本价·亏损",IF($Y9="","⚠️目标不可达·需降本",IF($E9<$Y9,"⚠️低于红线·未达目标利润率","✅达目标利润率"))))))
B10: =IFERROR(VLOOKUP($A10,SKU主表!$A:$M,2,0),"") | C10: =IFERROR(VLOOKUP($A10,SKU主表!$A:$M,9,0),"") | D10: =IFERROR(VLOOKUP($A10,SKU主表!$A:$M,5,0),"") | H10: =参数配置!$B$6 -> 0.0846 | I10: =IF($D10="","",$D10/参数配置!$B$5) | J10: =IF($E10="","",$E10*$H10) | K10: =IF($E10="","",$E10*参数配置!$B$7) | L10: =IF($E10="","",参数配置!$B$8) | M10: =IF($E10="","",$E10*参数配置!$B$9) | N10: =IF($E10="","",IF($E10<=参数配置!$B$11,$E10*参数配置!$B$10,0)) | O10: =IF($E10="","",$E10*$G10) | P10: =IF($E10="","",$E10*参数配置!$B$14) | Q10: =IF($E10="","",$E10*参数配置!$B$15) | R10: =IF($E10="","",$I10+$F10+$J10+$K10+$L10+$M10+$N10+$O10+$P10+$Q10) | S10: =IF($E10="","",$E10-$R10) | T10: =IF(OR($E10="",$E10=0),"",$S10/$E10) | U10: =IF($E10="","",$S10*参数配置!$B$5) | V10: =IF($E10="","",1-$H10-参数配置!$B$7-参数配置!$B$9-$G10-参数配置!$B$14-参数配置!$B$15-IF($E10<=参数配置!$B$11,参数配置!$B$10,0)) | W10: =IF($E10="","",$I10+$F10+$L10) | X10: =IF($E10="","",IF($V10>0,$W10/$V10,"")) | Y10: =IF($E10="","",IF(($V10-参数配置!$B$13)>0,$W10/($V10-参数配置!$B$13),"")) | Z10: =IF($E10="","",IF(OR($C10="禁售",$C10="需资质"),"⛔"&$C10&"·不应进入利润表",IF($V10<=0,"❗贡献率≤0·任何价都亏损",IF($E10<$X10,"⛔低于保本价·亏损",IF($Y10="","⚠️目标不可达·需降本",IF($E10<$Y10,"⚠️低于红线·未达目标利润率","✅达目标利润率"))))))
B11: =IFERROR(VLOOKUP($A11,SKU主表!$A:$M,2,0),"") | C11: =IFERROR(VLOOKUP($A11,SKU主表!$A:$M,9,0),"") | D11: =IFERROR(VLOOKUP($A11,SKU主表!$A:$M,5,0),"") | H11: =参数配置!$B$6 -> 0.0846 | I11: =IF($D11="","",$D11/参数配置!$B$5) | J11: =IF($E11="","",$E11*$H11) | K11: =IF($E11="","",$E11*参数配置!$B$7) | L11: =IF($E11="","",参数配置!$B$8) | M11: =IF($E11="","",$E11*参数配置!$B$9) | N11: =IF($E11="","",IF($E11<=参数配置!$B$11,$E11*参数配置!$B$10,0)) | O11: =IF($E11="","",$E11*$G11) | P11: =IF($E11="","",$E11*参数配置!$B$14) | Q11: =IF($E11="","",$E11*参数配置!$B$15) | R11: =IF($E11="","",$I11+$F11+$J11+$K11+$L11+$M11+$N11+$O11+$P11+$Q11) | S11: =IF($E11="","",$E11-$R11) | T11: =IF(OR($E11="",$E11=0),"",$S11/$E11) | U11: =IF($E11="","",$S11*参数配置!$B$5) | V11: =IF($E11="","",1-$H11-参数配置!$B$7-参数配置!$B$9-$G11-参数配置!$B$14-参数配置!$B$15-IF($E11<=参数配置!$B$11,参数配置!$B$10,0)) | W11: =IF($E11="","",$I11+$F11+$L11) | X11: =IF($E11="","",IF($V11>0,$W11/$V11,"")) | Y11: =IF($E11="","",IF(($V11-参数配置!$B$13)>0,$W11/($V11-参数配置!$B$13),"")) | Z11: =IF($E11="","",IF(OR($C11="禁售",$C11="需资质"),"⛔"&$C11&"·不应进入利润表",IF($V11<=0,"❗贡献率≤0·任何价都亏损",IF($E11<$X11,"⛔低于保本价·亏损",IF($Y11="","⚠️目标不可达·需降本",IF($E11<$Y11,"⚠️低于红线·未达目标利润率","✅达目标利润率"))))))
B12: =IFERROR(VLOOKUP($A12,SKU主表!$A:$M,2,0),"") | C12: =IFERROR(VLOOKUP($A12,SKU主表!$A:$M,9,0),"") | D12: =IFERROR(VLOOKUP($A12,SKU主表!$A:$M,5,0),"") | H12: =参数配置!$B$6 -> 0.0846 | I12: =IF($D12="","",$D12/参数配置!$B$5) | J12: =IF($E12="","",$E12*$H12) | K12: =IF($E12="","",$E12*参数配置!$B$7) | L12: =IF($E12="","",参数配置!$B$8) | M12: =IF($E12="","",$E12*参数配置!$B$9) | N12: =IF($E12="","",IF($E12<=参数配置!$B$11,$E12*参数配置!$B$10,0)) | O12: =IF($E12="","",$E12*$G12) | P12: =IF($E12="","",$E12*参数配置!$B$14) | Q12: =IF($E12="","",$E12*参数配置!$B$15) | R12: =IF($E12="","",$I12+$F12+$J12+$K12+$L12+$M12+$N12+$O12+$P12+$Q12) | S12: =IF($E12="","",$E12-$R12) | T12: =IF(OR($E12="",$E12=0),"",$S12/$E12) | U12: =IF($E12="","",$S12*参数配置!$B$5) | V12: =IF($E12="","",1-$H12-参数配置!$B$7-参数配置!$B$9-$G12-参数配置!$B$14-参数配置!$B$15-IF($E12<=参数配置!$B$11,参数配置!$B$10,0)) | W12: =IF($E12="","",$I12+$F12+$L12) | X12: =IF($E12="","",IF($V12>0,$W12/$V12,"")) | Y12: =IF($E12="","",IF(($V12-参数配置!$B$13)>0,$W12/($V12-参数配置!$B$13),"")) | Z12: =IF($E12="","",IF(OR($C12="禁售",$C12="需资质"),"⛔"&$C12&"·不应进入利润表",IF($V12<=0,"❗贡献率≤0·任何价都亏损",IF($E12<$X12,"⛔低于保本价·亏损",IF($Y12="","⚠️目标不可达·需降本",IF($E12<$Y12,"⚠️低于红线·未达目标利润率","✅达目标利润率"))))))
B13: =IFERROR(VLOOKUP($A13,SKU主表!$A:$M,2,0),"") | C13: =IFERROR(VLOOKUP($A13,SKU主表!$A:$M,9,0),"") | D13: =IFERROR(VLOOKUP($A13,SKU主表!$A:$M,5,0),"") | H13: =参数配置!$B$6 -> 0.0846 | I13: =IF($D13="","",$D13/参数配置!$B$5) | J13: =IF($E13="","",$E13*$H13) | K13: =IF($E13="","",$E13*参数配置!$B$7) | L13: =IF($E13="","",参数配置!$B$8) | M13: =IF($E13="","",$E13*参数配置!$B$9) | N13: =IF($E13="","",IF($E13<=参数配置!$B$11,$E13*参数配置!$B$10,0)) | O13: =IF($E13="","",$E13*$G13) | P13: =IF($E13="","",$E13*参数配置!$B$14) | Q13: =IF($E13="","",$E13*参数配置!$B$15) | R13: =IF($E13="","",$I13+$F13+$J13+$K13+$L13+$M13+$N13+$O13+$P13+$Q13) | S13: =IF($E13="","",$E13-$R13) | T13: =IF(OR($E13="",$E13=0),"",$S13/$E13) | U13: =IF($E13="","",$S13*参数配置!$B$5) | V13: =IF($E13="","",1-$H13-参数配置!$B$7-参数配置!$B$9-$G13-参数配置!$B$14-参数配置!$B$15-IF($E13<=参数配置!$B$11,参数配置!$B$10,0)) | W13: =IF($E13="","",$I13+$F13+$L13) | X13: =IF($E13="","",IF($V13>0,$W13/$V13,"")) | Y13: =IF($E13="","",IF(($V13-参数配置!$B$13)>0,$W13/($V13-参数配置!$B$13),"")) | Z13: =IF($E13="","",IF(OR($C13="禁售",$C13="需资质"),"⛔"&$C13&"·不应进入利润表",IF($V13<=0,"❗贡献率≤0·任何价都亏损",IF($E13<$X13,"⛔低于保本价·亏损",IF($Y13="","⚠️目标不可达·需降本",IF($E13<$Y13,"⚠️低于红线·未达目标利润率","✅达目标利润率"))))))
B14: =IFERROR(VLOOKUP($A14,SKU主表!$A:$M,2,0),"") | C14: =IFERROR(VLOOKUP($A14,SKU主表!$A:$M,9,0),"") | D14: =IFERROR(VLOOKUP($A14,SKU主表!$A:$M,5,0),"") | H14: =参数配置!$B$6 -> 0.0846 | I14: =IF($D14="","",$D14/参数配置!$B$5) | J14: =IF($E14="","",$E14*$H14) | K14: =IF($E14="","",$E14*参数配置!$B$7) | L14: =IF($E14="","",参数配置!$B$8) | M14: =IF($E14="","",$E14*参数配置!$B$9) | N14: =IF($E14="","",IF($E14<=参数配置!$B$11,$E14*参数配置!$B$10,0)) | O14: =IF($E14="","",$E14*$G14) | P14: =IF($E14="","",$E14*参数配置!$B$14) | Q14: =IF($E14="","",$E14*参数配置!$B$15) | R14: =IF($E14="","",$I14+$F14+$J14+$K14+$L14+$M14+$N14+$O14+$P14+$Q14) | S14: =IF($E14="","",$E14-$R14) | T14: =IF(OR($E14="",$E14=0),"",$S14/$E14) | U14: =IF($E14="","",$S14*参数配置!$B$5) | V14: =IF($E14="","",1-$H14-参数配置!$B$7-参数配置!$B$9-$G14-参数配置!$B$14-参数配置!$B$15-IF($E14<=参数配置!$B$11,参数配置!$B$10,0)) | W14: =IF($E14="","",$I14+$F14+$L14) | X14: =IF($E14="","",IF($V14>0,$W14/$V14,"")) | Y14: =IF($E14="","",IF(($V14-参数配置!$B$13)>0,$W14/($V14-参数配置!$B$13),"")) | Z14: =IF($E14="","",IF(OR($C14="禁售",$C14="需资质"),"⛔"&$C14&"·不应进入利润表",IF($V14<=0,"❗贡献率≤0·任何价都亏损",IF($E14<$X14,"⛔低于保本价·亏损",IF($Y14="","⚠️目标不可达·需降本",IF($E14<$Y14,"⚠️低于红线·未达目标利润率","✅达目标利润率"))))))
B15: =IFERROR(VLOOKUP($A15,SKU主表!$A:$M,2,0),"") | C15: =IFERROR(VLOOKUP($A15,SKU主表!$A:$M,9,0),"") | D15: =IFERROR(VLOOKUP($A15,SKU主表!$A:$M,5,0),"") | H15: =参数配置!$B$6 -> 0.0846 | I15: =IF($D15="","",$D15/参数配置!$B$5) | J15: =IF($E15="","",$E15*$H15) | K15: =IF($E15="","",$E15*参数配置!$B$7) | L15: =IF($E15="","",参数配置!$B$8) | M15: =IF($E15="","",$E15*参数配置!$B$9) | N15: =IF($E15="","",IF($E15<=参数配置!$B$11,$E15*参数配置!$B$10,0)) | O15: =IF($E15="","",$E15*$G15) | P15: =IF($E15="","",$E15*参数配置!$B$14) | Q15: =IF($E15="","",$E15*参数配置!$B$15) | R15: =IF($E15="","",$I15+$F15+$J15+$K15+$L15+$M15+$N15+$O15+$P15+$Q15) | S15: =IF($E15="","",$E15-$R15) | T15: =IF(OR($E15="",$E15=0),"",$S15/$E15) | U15: =IF($E15="","",$S15*参数配置!$B$5) | V15: =IF($E15="","",1-$H15-参数配置!$B$7-参数配置!$B$9-$G15-参数配置!$B$14-参数配置!$B$15-IF($E15<=参数配置!$B$11,参数配置!$B$10,0)) | W15: =IF($E15="","",$I15+$F15+$L15) | X15: =IF($E15="","",IF($V15>0,$W15/$V15,"")) | Y15: =IF($E15="","",IF(($V15-参数配置!$B$13)>0,$W15/($V15-参数配置!$B$13),"")) | Z15: =IF($E15="","",IF(OR($C15="禁售",$C15="需资质"),"⛔"&$C15&"·不应进入利润表",IF($V15<=0,"❗贡献率≤0·任何价都亏损",IF($E15<$X15,"⛔低于保本价·亏损",IF($Y15="","⚠️目标不可达·需降本",IF($E15<$Y15,"⚠️低于红线·未达目标利润率","✅达目标利润率"))))))
B16: =IFERROR(VLOOKUP($A16,SKU主表!$A:$M,2,0),"") | C16: =IFERROR(VLOOKUP($A16,SKU主表!$A:$M,9,0),"") | D16: =IFERROR(VLOOKUP($A16,SKU主表!$A:$M,5,0),"") | H16: =参数配置!$B$6 -> 0.0846 | I16: =IF($D16="","",$D16/参数配置!$B$5) | J16: =IF($E16="","",$E16*$H16) | K16: =IF($E16="","",$E16*参数配置!$B$7) | L16: =IF($E16="","",参数配置!$B$8) | M16: =IF($E16="","",$E16*参数配置!$B$9) | N16: =IF($E16="","",IF($E16<=参数配置!$B$11,$E16*参数配置!$B$10,0)) | O16: =IF($E16="","",$E16*$G16) | P16: =IF($E16="","",$E16*参数配置!$B$14) | Q16: =IF($E16="","",$E16*参数配置!$B$15) | R16: =IF($E16="","",$I16+$F16+$J16+$K16+$L16+$M16+$N16+$O16+$P16+$Q16) | S16: =IF($E16="","",$E16-$R16) | T16: =IF(OR($E16="",$E16=0),"",$S16/$E16) | U16: =IF($E16="","",$S16*参数配置!$B$5) | V16: =IF($E16="","",1-$H16-参数配置!$B$7-参数配置!$B$9-$G16-参数配置!$B$14-参数配置!$B$15-IF($E16<=参数配置!$B$11,参数配置!$B$10,0)) | W16: =IF($E16="","",$I16+$F16+$L16) | X16: =IF($E16="","",IF($V16>0,$W16/$V16,"")) | Y16: =IF($E16="","",IF(($V16-参数配置!$B$13)>0,$W16/($V16-参数配置!$B$13),"")) | Z16: =IF($E16="","",IF(OR($C16="禁售",$C16="需资质"),"⛔"&$C16&"·不应进入利润表",IF($V16<=0,"❗贡献率≤0·任何价都亏损",IF($E16<$X16,"⛔低于保本价·亏损",IF($Y16="","⚠️目标不可达·需降本",IF($E16<$Y16,"⚠️低于红线·未达目标利润率","✅达目标利润率"))))))
B17: =IFERROR(VLOOKUP($A17,SKU主表!$A:$M,2,0),"") | C17: =IFERROR(VLOOKUP($A17,SKU主表!$A:$M,9,0),"") | D17: =IFERROR(VLOOKUP($A17,SKU主表!$A:$M,5,0),"") | H17: =参数配置!$B$6 -> 0.0846 | I17: =IF($D17="","",$D17/参数配置!$B$5) | J17: =IF($E17="","",$E17*$H17) | K17: =IF($E17="","",$E17*参数配置!$B$7) | L17: =IF($E17="","",参数配置!$B$8) | M17: =IF($E17="","",$E17*参数配置!$B$9) | N17: =IF($E17="","",IF($E17<=参数配置!$B$11,$E17*参数配置!$B$10,0)) | O17: =IF($E17="","",$E17*$G17) | P17: =IF($E17="","",$E17*参数配置!$B$14) | Q17: =IF($E17="","",$E17*参数配置!$B$15) | R17: =IF($E17="","",$I17+$F17+$J17+$K17+$L17+$M17+$N17+$O17+$P17+$Q17) | S17: =IF($E17="","",$E17-$R17) | T17: =IF(OR($E17="",$E17=0),"",$S17/$E17) | U17: =IF($E17="","",$S17*参数配置!$B$5) | V17: =IF($E17="","",1-$H17-参数配置!$B$7-参数配置!$B$9-$G17-参数配置!$B$14-参数配置!$B$15-IF($E17<=参数配置!$B$11,参数配置!$B$10,0)) | W17: =IF($E17="","",$I17+$F17+$L17) | X17: =IF($E17="","",IF($V17>0,$W17/$V17,"")) | Y17: =IF($E17="","",IF(($V17-参数配置!$B$13)>0,$W17/($V17-参数配置!$B$13),"")) | Z17: =IF($E17="","",IF(OR($C17="禁售",$C17="需资质"),"⛔"&$C17&"·不应进入利润表",IF($V17<=0,"❗贡献率≤0·任何价都亏损",IF($E17<$X17,"⛔低于保本价·亏损",IF($Y17="","⚠️目标不可达·需降本",IF($E17<$Y17,"⚠️低于红线·未达目标利润率","✅达目标利润率"))))))
B18: =IFERROR(VLOOKUP($A18,SKU主表!$A:$M,2,0),"") | C18: =IFERROR(VLOOKUP($A18,SKU主表!$A:$M,9,0),"") | D18: =IFERROR(VLOOKUP($A18,SKU主表!$A:$M,5,0),"") | H18: =参数配置!$B$6 -> 0.0846 | I18: =IF($D18="","",$D18/参数配置!$B$5) | J18: =IF($E18="","",$E18*$H18) | K18: =IF($E18="","",$E18*参数配置!$B$7) | L18: =IF($E18="","",参数配置!$B$8) | M18: =IF($E18="","",$E18*参数配置!$B$9) | N18: =IF($E18="","",IF($E18<=参数配置!$B$11,$E18*参数配置!$B$10,0)) | O18: =IF($E18="","",$E18*$G18) | P18: =IF($E18="","",$E18*参数配置!$B$14) | Q18: =IF($E18="","",$E18*参数配置!$B$15) | R18: =IF($E18="","",$I18+$F18+$J18+$K18+$L18+$M18+$N18+$O18+$P18+$Q18) | S18: =IF($E18="","",$E18-$R18) | T18: =IF(OR($E18="",$E18=0),"",$S18/$E18) | U18: =IF($E18="","",$S18*参数配置!$B$5) | V18: =IF($E18="","",1-$H18-参数配置!$B$7-参数配置!$B$9-$G18-参数配置!$B$14-参数配置!$B$15-IF($E18<=参数配置!$B$11,参数配置!$B$10,0)) | W18: =IF($E18="","",$I18+$F18+$L18) | X18: =IF($E18="","",IF($V18>0,$W18/$V18,"")) | Y18: =IF($E18="","",IF(($V18-参数配置!$B$13)>0,$W18/($V18-参数配置!$B$13),"")) | Z18: =IF($E18="","",IF(OR($C18="禁售",$C18="需资质"),"⛔"&$C18&"·不应进入利润表",IF($V18<=0,"❗贡献率≤0·任何价都亏损",IF($E18<$X18,"⛔低于保本价·亏损",IF($Y18="","⚠️目标不可达·需降本",IF($E18<$Y18,"⚠️低于红线·未达目标利润率","✅达目标利润率"))))))
B19: =IFERROR(VLOOKUP($A19,SKU主表!$A:$M,2,0),"") | C19: =IFERROR(VLOOKUP($A19,SKU主表!$A:$M,9,0),"") | D19: =IFERROR(VLOOKUP($A19,SKU主表!$A:$M,5,0),"") | H19: =参数配置!$B$6 -> 0.0846 | I19: =IF($D19="","",$D19/参数配置!$B$5) | J19: =IF($E19="","",$E19*$H19) | K19: =IF($E19="","",$E19*参数配置!$B$7) | L19: =IF($E19="","",参数配置!$B$8) | M19: =IF($E19="","",$E19*参数配置!$B$9) | N19: =IF($E19="","",IF($E19<=参数配置!$B$11,$E19*参数配置!$B$10,0)) | O19: =IF($E19="","",$E19*$G19) | P19: =IF($E19="","",$E19*参数配置!$B$14) | Q19: =IF($E19="","",$E19*参数配置!$B$15) | R19: =IF($E19="","",$I19+$F19+$J19+$K19+$L19+$M19+$N19+$O19+$P19+$Q19) | S19: =IF($E19="","",$E19-$R19) | T19: =IF(OR($E19="",$E19=0),"",$S19/$E19) | U19: =IF($E19="","",$S19*参数配置!$B$5) | V19: =IF($E19="","",1-$H19-参数配置!$B$7-参数配置!$B$9-$G19-参数配置!$B$14-参数配置!$B$15-IF($E19<=参数配置!$B$11,参数配置!$B$10,0)) | W19: =IF($E19="","",$I19+$F19+$L19) | X19: =IF($E19="","",IF($V19>0,$W19/$V19,"")) | Y19: =IF($E19="","",IF(($V19-参数配置!$B$13)>0,$W19/($V19-参数配置!$B$13),"")) | Z19: =IF($E19="","",IF(OR($C19="禁售",$C19="需资质"),"⛔"&$C19&"·不应进入利润表",IF($V19<=0,"❗贡献率≤0·任何价都亏损",IF($E19<$X19,"⛔低于保本价·亏损",IF($Y19="","⚠️目标不可达·需降本",IF($E19<$Y19,"⚠️低于红线·未达目标利润率","✅达目标利润率"))))))
B20: =IFERROR(VLOOKUP($A20,SKU主表!$A:$M,2,0),"") | C20: =IFERROR(VLOOKUP($A20,SKU主表!$A:$M,9,0),"") | D20: =IFERROR(VLOOKUP($A20,SKU主表!$A:$M,5,0),"") | H20: =参数配置!$B$6 -> 0.0846 | I20: =IF($D20="","",$D20/参数配置!$B$5) | J20: =IF($E20="","",$E20*$H20) | K20: =IF($E20="","",$E20*参数配置!$B$7) | L20: =IF($E20="","",参数配置!$B$8) | M20: =IF($E20="","",$E20*参数配置!$B$9) | N20: =IF($E20="","",IF($E20<=参数配置!$B$11,$E20*参数配置!$B$10,0)) | O20: =IF($E20="","",$E20*$G20) | P20: =IF($E20="","",$E20*参数配置!$B$14) | Q20: =IF($E20="","",$E20*参数配置!$B$15) | R20: =IF($E20="","",$I20+$F20+$J20+$K20+$L20+$M20+$N20+$O20+$P20+$Q20) | S20: =IF($E20="","",$E20-$R20) | T20: =IF(OR($E20="",$E20=0),"",$S20/$E20) | U20: =IF($E20="","",$S20*参数配置!$B$5) | V20: =IF($E20="","",1-$H20-参数配置!$B$7-参数配置!$B$9-$G20-参数配置!$B$14-参数配置!$B$15-IF($E20<=参数配置!$B$11,参数配置!$B$10,0)) | W20: =IF($E20="","",$I20+$F20+$L20) | X20: =IF($E20="","",IF($V20>0,$W20/$V20,"")) | Y20: =IF($E20="","",IF(($V20-参数配置!$B$13)>0,$W20/($V20-参数配置!$B$13),"")) | Z20: =IF($E20="","",IF(OR($C20="禁售",$C20="需资质"),"⛔"&$C20&"·不应进入利润表",IF($V20<=0,"❗贡献率≤0·任何价都亏损",IF($E20<$X20,"⛔低于保本价·亏损",IF($Y20="","⚠️目标不可达·需降本",IF($E20<$Y20,"⚠️低于红线·未达目标利润率","✅达目标利润率"))))))
... B33: =IFERROR(VLOOKUP($A33,SKU主表!$A:$M,2,0),"") | C33: =IFERROR(VLOOKUP($A33,SKU主表!$A:$M,9,0),"") | D33: =IFERROR(VLOOKUP($A33,SKU主表!$A:$M,5,0),"") | H33: =参数配置!$B$6 -> 0.0846 | I33: =IF($D33="","",$D33/参数配置!$B$5) | J33: =IF($E33="","",$E33*$H33) | K33: =IF($E33="","",$E33*参数配置!$B$7) | L33: =IF($E33="","",参数配置!$B$8) | M33: =IF($E33="","",$E33*参数配置!$B$9) | N33: =IF($E33="","",IF($E33<=参数配置!$B$11,$E33*参数配置!$B$10,0)) | O33: =IF($E33="","",$E33*$G33) | P33: =IF($E33="","",$E33*参数配置!$B$14) | Q33: =IF($E33="","",$E33*参数配置!$B$15) | R33: =IF($E33="","",$I33+$F33+$J33+$K33+$L33+$M33+$N33+$O33+$P33+$Q33) | S33: =IF($E33="","",$E33-$R33) | T33: =IF(OR($E33="",$E33=0),"",$S33/$E33) | U33: =IF($E33="","",$S33*参数配置!$B$5) | V33: =IF($E33="","",1-$H33-参数配置!$B$7-参数配置!$B$9-$G33-参数配置!$B$14-参数配置!$B$15-IF($E33<=参数配置!$B$11,参数配置!$B$10,0)) | W33: =IF($E33="","",$I33+$F33+$L33) | X33: =IF($E33="","",IF($V33>0,$W33/$V33,"")) | Y33: =IF($E33="","",IF(($V33-参数配置!$B$13)>0,$W33/($V33-参数配置!$B$13),"")) | Z33: =IF($E33="","",IF(OR($C33="禁售",$C33="需资质"),"⛔"&$C33&"·不应进入利润表",IF($V33<=0,"❗贡献率≤0·任何价都亏损",IF($E33<$X33,"⛔低于保本价·亏损",IF($Y33="","⚠️目标不可达·需降本",IF($E33<$Y33,"⚠️低于红线·未达目标利润率","✅达目标利润率"))))))

Sheet 商品四象限分层
A1: 商品四象限分层 · 漏斗诊断 + 自动建议
A2: 上架后回填 曝光/点击/加购/成交/退款（蓝色）。三段漏斗：点击率=点击/曝光、加购率=加购/点击、成交率=成交/加购。流量轴(曝光)×转化轴(成交率)对『参数配置』阈值→自动判象限+建议动作。
A3: 编号 | B3: 品名 | C3: 曝光 | D3: 点击 | E3: 加购 | F3: 成交 | G3: 退款 | H3: 点击率 | I3: 加购率 | J3: 成交率(成交/加购) | K3: 退款率 | L3: 流量分层 | M3: 转化分层 | N3: 象限 | O3: 建议动作 | P3: 退款预警
A4: TKMY-001 | B4: =IFERROR(VLOOKUP($A4,SKU主表!$A:$M,2,0),"") -> 印花头巾 Hijab Bawal Printed | C4: 5000 | D4: 400 | E4: 120 | F4: 36 | G4: 2 | H4: =IFERROR($D4/$C4,"") -> 0.08 | I4: =IFERROR($E4/$D4,"") -> 0.3 | J4: =IFERROR($F4/$E4,"") -> 0.3 | K4: =IFERROR($G4/$F4,"") -> 0.055555556 | L4: =IF($C4="","",IF($C4>=参数配置!$B$19,"高流量","低流量")) -> 高流量 | M4: =IF($J4="","",IF($J4>=参数配置!$B$20,"高转化","低转化")) -> 高转化 | N4: =IF(OR($L4="",$M4=""),"",$L4&$M4) -> 高流量高转化 | O4: =IF($N4="","",IF($N4="高流量高转化","主推：加库存/上活动/扩达人/试投流",IF($N4="高流量低转化","查转化：价格/运费/优惠券/主图/详情/评价/客服",IF($N4="低流量高转化","加曝光：达人/短视频/直播/商城活动+秒杀",IF($N4="低流量低转化","下架或改图改标题重测/放弃",""))))) -> 主推：加库存/上活动/扩达人/试投流 | P4: =IF($K4="","",IF($K4>参数配置!$B$21,"⚠️退款率偏高·查质量/尺码/物流",""))
A5: TKMY-002 | B5: =IFERROR(VLOOKUP($A5,SKU主表!$A:$M,2,0),"") -> 折叠除湿盒 Kotak Penyahlembap | C5: 600 | D5: 60 | E5: 12 | F5: 4 | G5: 1 | H5: =IFERROR($D5/$C5,"") -> 0.1 | I5: =IFERROR($E5/$D5,"") -> 0.2 | J5: =IFERROR($F5/$E5,"") -> 0.33333333 | K5: =IFERROR($G5/$F5,"") -> 0.25 | L5: =IF($C5="","",IF($C5>=参数配置!$B$19,"高流量","低流量")) -> 低流量 | M5: =IF($J5="","",IF($J5>=参数配置!$B$20,"高转化","低转化")) -> 高转化 | N5: =IF(OR($L5="",$M5=""),"",$L5&$M5) -> 低流量高转化 | O5: =IF($N5="","",IF($N5="高流量高转化","主推：加库存/上活动/扩达人/试投流",IF($N5="高流量低转化","查转化：价格/运费/优惠券/主图/详情/评价/客服",IF($N5="低流量高转化","加曝光：达人/短视频/直播/商城活动+秒杀",IF($N5="低流量低转化","下架或改图改标题重测/放弃",""))))) -> 加曝光：达人/短视频/直播/商城活动+秒杀 | P5: =IF($K5="","",IF($K5>参数配置!$B$21,"⚠️退款率偏高·查质量/尺码/物流","")) -> ⚠️退款率偏高·查质量/尺码/物流
A6: TKMY-001 | B6: =IFERROR(VLOOKUP($A6,SKU主表!$A:$M,2,0),"") -> 印花头巾 Hijab Bawal Printed | C6: 9000 | D6: 300 | E6: 40 | F6: 1 | G6: 0 | H6: =IFERROR($D6/$C6,"") -> 0.033333333 | I6: =IFERROR($E6/$D6,"") -> 0.13333333 | J6: =IFERROR($F6/$E6,"") -> 0.025 | K6: =IFERROR($G6/$F6,"") -> 0 | L6: =IF($C6="","",IF($C6>=参数配置!$B$19,"高流量","低流量")) -> 高流量 | M6: =IF($J6="","",IF($J6>=参数配置!$B$20,"高转化","低转化")) -> 低转化 | N6: =IF(OR($L6="",$M6=""),"",$L6&$M6) -> 高流量低转化 | O6: =IF($N6="","",IF($N6="高流量高转化","主推：加库存/上活动/扩达人/试投流",IF($N6="高流量低转化","查转化：价格/运费/优惠券/主图/详情/评价/客服",IF($N6="低流量高转化","加曝光：达人/短视频/直播/商城活动+秒杀",IF($N6="低流量低转化","下架或改图改标题重测/放弃",""))))) -> 查转化：价格/运费/优惠券/主图/详情/评价/客服 | P6: =IF($K6="","",IF($K6>参数配置!$B$21,"⚠️退款率偏高·查质量/尺码/物流",""))
A7: TKMY-002 | B7: =IFERROR(VLOOKUP($A7,SKU主表!$A:$M,2,0),"") -> 折叠除湿盒 Kotak Penyahlembap | C7: 500 | D7: 40 | E7: 5 | F7: 0 | G7: 0 | H7: =IFERROR($D7/$C7,"") -> 0.08 | I7: =IFERROR($E7/$D7,"") -> 0.125 | J7: =IFERROR($F7/$E7,"") -> 0 | K7: =IFERROR($G7/$F7,"") | L7: =IF($C7="","",IF($C7>=参数配置!$B$19,"高流量","低流量")) -> 低流量 | M7: =IF($J7="","",IF($J7>=参数配置!$B$20,"高转化","低转化")) -> 低转化 | N7: =IF(OR($L7="",$M7=""),"",$L7&$M7) -> 低流量低转化 | O7: =IF($N7="","",IF($N7="高流量高转化","主推：加库存/上活动/扩达人/试投流",IF($N7="高流量低转化","查转化：价格/运费/优惠券/主图/详情/评价/客服",IF($N7="低流量高转化","加曝光：达人/短视频/直播/商城活动+秒杀",IF($N7="低流量低转化","下架或改图改标题重测/放弃",""))))) -> 下架或改图改标题重测/放弃 | P7: =IF($K7="","",IF($K7>参数配置!$B$21,"⚠️退款率偏高·查质量/尺码/物流",""))
B8: =IFERROR(VLOOKUP($A8,SKU主表!$A:$M,2,0),"") | H8: =IFERROR($D8/$C8,"") | I8: =IFERROR($E8/$D8,"") | J8: =IFERROR($F8/$E8,"") | K8: =IFERROR($G8/$F8,"") | L8: =IF($C8="","",IF($C8>=参数配置!$B$19,"高流量","低流量")) | M8: =IF($J8="","",IF($J8>=参数配置!$B$20,"高转化","低转化")) | N8: =IF(OR($L8="",$M8=""),"",$L8&$M8) | O8: =IF($N8="","",IF($N8="高流量高转化","主推：加库存/上活动/扩达人/试投流",IF($N8="高流量低转化","查转化：价格/运费/优惠券/主图/详情/评价/客服",IF($N8="低流量高转化","加曝光：达人/短视频/直播/商城活动+秒杀",IF($N8="低流量低转化","下架或改图改标题重测/放弃",""))))) | P8: =IF($K8="","",IF($K8>参数配置!$B$21,"⚠️退款率偏高·查质量/尺码/物流",""))
B9: =IFERROR(VLOOKUP($A9,SKU主表!$A:$M,2,0),"") | H9: =IFERROR($D9/$C9,"") | I9: =IFERROR($E9/$D9,"") | J9: =IFERROR($F9/$E9,"") | K9: =IFERROR($G9/$F9,"") | L9: =IF($C9="","",IF($C9>=参数配置!$B$19,"高流量","低流量")) | M9: =IF($J9="","",IF($J9>=参数配置!$B$20,"高转化","低转化")) | N9: =IF(OR($L9="",$M9=""),"",$L9&$M9) | O9: =IF($N9="","",IF($N9="高流量高转化","主推：加库存/上活动/扩达人/试投流",IF($N9="高流量低转化","查转化：价格/运费/优惠券/主图/详情/评价/客服",IF($N9="低流量高转化","加曝光：达人/短视频/直播/商城活动+秒杀",IF($N9="低流量低转化","下架或改图改标题重测/放弃",""))))) | P9: =IF($K9="","",IF($K9>参数配置!$B$21,"⚠️退款率偏高·查质量/尺码/物流",""))
B10: =IFERROR(VLOOKUP($A10,SKU主表!$A:$M,2,0),"") | H10: =IFERROR($D10/$C10,"") | I10: =IFERROR($E10/$D10,"") | J10: =IFERROR($F10/$E10,"") | K10: =IFERROR($G10/$F10,"") | L10: =IF($C10="","",IF($C10>=参数配置!$B$19,"高流量","低流量")) | M10: =IF($J10="","",IF($J10>=参数配置!$B$20,"高转化","低转化")) | N10: =IF(OR($L10="",$M10=""),"",$L10&$M10) | O10: =IF($N10="","",IF($N10="高流量高转化","主推：加库存/上活动/扩达人/试投流",IF($N10="高流量低转化","查转化：价格/运费/优惠券/主图/详情/评价/客服",IF($N10="低流量高转化","加曝光：达人/短视频/直播/商城活动+秒杀",IF($N10="低流量低转化","下架或改图改标题重测/放弃",""))))) | P10: =IF($K10="","",IF($K10>参数配置!$B$21,"⚠️退款率偏高·查质量/尺码/物流",""))
B11: =IFERROR(VLOOKUP($A11,SKU主表!$A:$M,2,0),"") | H11: =IFERROR($D11/$C11,"") | I11: =IFERROR($E11/$D11,"") | J11: =IFERROR($F11/$E11,"") | K11: =IFERROR($G11/$F11,"") | L11: =IF($C11="","",IF($C11>=参数配置!$B$19,"高流量","低流量")) | M11: =IF($J11="","",IF($J11>=参数配置!$B$20,"高转化","低转化")) | N11: =IF(OR($L11="",$M11=""),"",$L11&$M11) | O11: =IF($N11="","",IF($N11="高流量高转化","主推：加库存/上活动/扩达人/试投流",IF($N11="高流量低转化","查转化：价格/运费/优惠券/主图/详情/评价/客服",IF($N11="低流量高转化","加曝光：达人/短视频/直播/商城活动+秒杀",IF($N11="低流量低转化","下架或改图改标题重测/放弃",""))))) | P11: =IF($K11="","",IF($K11>参数配置!$B$21,"⚠️退款率偏高·查质量/尺码/物流",""))
B12: =IFERROR(VLOOKUP($A12,SKU主表!$A:$M,2,0),"") | H12: =IFERROR($D12/$C12,"") | I12: =IFERROR($E12/$D12,"") | J12: =IFERROR($F12/$E12,"") | K12: =IFERROR($G12/$F12,"") | L12: =IF($C12="","",IF($C12>=参数配置!$B$19,"高流量","低流量")) | M12: =IF($J12="","",IF($J12>=参数配置!$B$20,"高转化","低转化")) | N12: =IF(OR($L12="",$M12=""),"",$L12&$M12) | O12: =IF($N12="","",IF($N12="高流量高转化","主推：加库存/上活动/扩达人/试投流",IF($N12="高流量低转化","查转化：价格/运费/优惠券/主图/详情/评价/客服",IF($N12="低流量高转化","加曝光：达人/短视频/直播/商城活动+秒杀",IF($N12="低流量低转化","下架或改图改标题重测/放弃",""))))) | P12: =IF($K12="","",IF($K12>参数配置!$B$21,"⚠️退款率偏高·查质量/尺码/物流",""))
B13: =IFERROR(VLOOKUP($A13,SKU主表!$A:$M,2,0),"") | H13: =IFERROR($D13/$C13,"") | I13: =IFERROR($E13/$D13,"") | J13: =IFERROR($F13/$E13,"") | K13: =IFERROR($G13/$F13,"") | L13: =IF($C13="","",IF($C13>=参数配置!$B$19,"高流量","低流量")) | M13: =IF($J13="","",IF($J13>=参数配置!$B$20,"高转化","低转化")) | N13: =IF(OR($L13="",$M13=""),"",$L13&$M13) | O13: =IF($N13="","",IF($N13="高流量高转化","主推：加库存/上活动/扩达人/试投流",IF($N13="高流量低转化","查转化：价格/运费/优惠券/主图/详情/评价/客服",IF($N13="低流量高转化","加曝光：达人/短视频/直播/商城活动+秒杀",IF($N13="低流量低转化","下架或改图改标题重测/放弃",""))))) | P13: =IF($K13="","",IF($K13>参数配置!$B$21,"⚠️退款率偏高·查质量/尺码/物流",""))
B14: =IFERROR(VLOOKUP($A14,SKU主表!$A:$M,2,0),"") | H14: =IFERROR($D14/$C14,"") | I14: =IFERROR($E14/$D14,"") | J14: =IFERROR($F14/$E14,"") | K14: =IFERROR($G14/$F14,"") | L14: =IF($C14="","",IF($C14>=参数配置!$B$19,"高流量","低流量")) | M14: =IF($J14="","",IF($J14>=参数配置!$B$20,"高转化","低转化")) | N14: =IF(OR($L14="",$M14=""),"",$L14&$M14) | O14: =IF($N14="","",IF($N14="高流量高转化","主推：加库存/上活动/扩达人/试投流",IF($N14="高流量低转化","查转化：价格/运费/优惠券/主图/详情/评价/客服",IF($N14="低流量高转化","加曝光：达人/短视频/直播/商城活动+秒杀",IF($N14="低流量低转化","下架或改图改标题重测/放弃",""))))) | P14: =IF($K14="","",IF($K14>参数配置!$B$21,"⚠️退款率偏高·查质量/尺码/物流",""))
B15: =IFERROR(VLOOKUP($A15,SKU主表!$A:$M,2,0),"") | H15: =IFERROR($D15/$C15,"") | I15: =IFERROR($E15/$D15,"") | J15: =IFERROR($F15/$E15,"") | K15: =IFERROR($G15/$F15,"") | L15: =IF($C15="","",IF($C15>=参数配置!$B$19,"高流量","低流量")) | M15: =IF($J15="","",IF($J15>=参数配置!$B$20,"高转化","低转化")) | N15: =IF(OR($L15="",$M15=""),"",$L15&$M15) | O15: =IF($N15="","",IF($N15="高流量高转化","主推：加库存/上活动/扩达人/试投流",IF($N15="高流量低转化","查转化：价格/运费/优惠券/主图/详情/评价/客服",IF($N15="低流量高转化","加曝光：达人/短视频/直播/商城活动+秒杀",IF($N15="低流量低转化","下架或改图改标题重测/放弃",""))))) | P15: =IF($K15="","",IF($K15>参数配置!$B$21,"⚠️退款率偏高·查质量/尺码/物流",""))
B16: =IFERROR(VLOOKUP($A16,SKU主表!$A:$M,2,0),"") | H16: =IFERROR($D16/$C16,"") | I16: =IFERROR($E16/$D16,"") | J16: =IFERROR($F16/$E16,"") | K16: =IFERROR($G16/$F16,"") | L16: =IF($C16="","",IF($C16>=参数配置!$B$19,"高流量","低流量")) | M16: =IF($J16="","",IF($J16>=参数配置!$B$20,"高转化","低转化")) | N16: =IF(OR($L16="",$M16=""),"",$L16&$M16) | O16: =IF($N16="","",IF($N16="高流量高转化","主推：加库存/上活动/扩达人/试投流",IF($N16="高流量低转化","查转化：价格/运费/优惠券/主图/详情/评价/客服",IF($N16="低流量高转化","加曝光：达人/短视频/直播/商城活动+秒杀",IF($N16="低流量低转化","下架或改图改标题重测/放弃",""))))) | P16: =IF($K16="","",IF($K16>参数配置!$B$21,"⚠️退款率偏高·查质量/尺码/物流",""))
B17: =IFERROR(VLOOKUP($A17,SKU主表!$A:$M,2,0),"") | H17: =IFERROR($D17/$C17,"") | I17: =IFERROR($E17/$D17,"") | J17: =IFERROR($F17/$E17,"") | K17: =IFERROR($G17/$F17,"") | L17: =IF($C17="","",IF($C17>=参数配置!$B$19,"高流量","低流量")) | M17: =IF($J17="","",IF($J17>=参数配置!$B$20,"高转化","低转化")) | N17: =IF(OR($L17="",$M17=""),"",$L17&$M17) | O17: =IF($N17="","",IF($N17="高流量高转化","主推：加库存/上活动/扩达人/试投流",IF($N17="高流量低转化","查转化：价格/运费/优惠券/主图/详情/评价/客服",IF($N17="低流量高转化","加曝光：达人/短视频/直播/商城活动+秒杀",IF($N17="低流量低转化","下架或改图改标题重测/放弃",""))))) | P17: =IF($K17="","",IF($K17>参数配置!$B$21,"⚠️退款率偏高·查质量/尺码/物流",""))
B18: =IFERROR(VLOOKUP($A18,SKU主表!$A:$M,2,0),"") | H18: =IFERROR($D18/$C18,"") | I18: =IFERROR($E18/$D18,"") | J18: =IFERROR($F18/$E18,"") | K18: =IFERROR($G18/$F18,"") | L18: =IF($C18="","",IF($C18>=参数配置!$B$19,"高流量","低流量")) | M18: =IF($J18="","",IF($J18>=参数配置!$B$20,"高转化","低转化")) | N18: =IF(OR($L18="",$M18=""),"",$L18&$M18) | O18: =IF($N18="","",IF($N18="高流量高转化","主推：加库存/上活动/扩达人/试投流",IF($N18="高流量低转化","查转化：价格/运费/优惠券/主图/详情/评价/客服",IF($N18="低流量高转化","加曝光：达人/短视频/直播/商城活动+秒杀",IF($N18="低流量低转化","下架或改图改标题重测/放弃",""))))) | P18: =IF($K18="","",IF($K18>参数配置!$B$21,"⚠️退款率偏高·查质量/尺码/物流",""))
B19: =IFERROR(VLOOKUP($A19,SKU主表!$A:$M,2,0),"") | H19: =IFERROR($D19/$C19,"") | I19: =IFERROR($E19/$D19,"") | J19: =IFERROR($F19/$E19,"") | K19: =IFERROR($G19/$F19,"") | L19: =IF($C19="","",IF($C19>=参数配置!$B$19,"高流量","低流量")) | M19: =IF($J19="","",IF($J19>=参数配置!$B$20,"高转化","低转化")) | N19: =IF(OR($L19="",$M19=""),"",$L19&$M19) | O19: =IF($N19="","",IF($N19="高流量高转化","主推：加库存/上活动/扩达人/试投流",IF($N19="高流量低转化","查转化：价格/运费/优惠券/主图/详情/评价/客服",IF($N19="低流量高转化","加曝光：达人/短视频/直播/商城活动+秒杀",IF($N19="低流量低转化","下架或改图改标题重测/放弃",""))))) | P19: =IF($K19="","",IF($K19>参数配置!$B$21,"⚠️退款率偏高·查质量/尺码/物流",""))
... B33: =IFERROR(VLOOKUP($A33,SKU主表!$A:$M,2,0),"") | H33: =IFERROR($D33/$C33,"") | I33: =IFERROR($E33/$D33,"") | J33: =IFERROR($F33/$E33,"") | K33: =IFERROR($G33/$F33,"") | L33: =IF($C33="","",IF($C33>=参数配置!$B$19,"高流量","低流量")) | M33: =IF($J33="","",IF($J33>=参数配置!$B$20,"高转化","低转化")) | N33: =IF(OR($L33="",$M33=""),"",$L33&$M33) | O33: =IF($N33="","",IF($N33="高流量高转化","主推：加库存/上活动/扩达人/试投流",IF($N33="高流量低转化","查转化：价格/运费/优惠券/主图/详情/评价/客服",IF($N33="低流量高转化","加曝光：达人/短视频/直播/商城活动+秒杀",IF($N33="低流量低转化","下架或改图改标题重测/放弃",""))))) | P33: =IF($K33="","",IF($K33>参数配置!$B$21,"⚠️退款率偏高·查质量/尺码/物流",""))

Sheet 达人邀约话术
A1: 达人邀约话术库 · 马来西亚（联系渠道优先 WhatsApp）
A2: 用法：复制话术 → 替换 [占位符] → 本地化润色后发送。占位符：[达人昵称]=creator｜[视频内容]=对方视频主题｜[品类]/[卖点]=你的货｜[X]%=佣金｜[物流单号][视频链接][金额][新品][脚本链接][店铺名][你的名字]。原则：简短·emoji点缀·提对方具体视频·讲清利益点·尊重意愿·多版本A/B测试。佣金率示例 5%(视频)/8–15%(主推直播)，均为示例，签约前以谈判与后台为准。
A3: 场景 | B3: 渠道 | C3: 语言 | D3: 话术（含 [占位符]） | E3: 备注
A4: 破冰·官方参考 | B4: WhatsApp | C4: English | D4: Hi [达人昵称]! Love your video about [视频内容]! Our new store has similar [品类] that would look perfect on you. Would you be open to a free sample? 😊 | E4: 官方参考破冰；务必提到对方具体视频，避免群发被识破。
A5: 破冰·官方参考 | B5: WhatsApp | C5: Bahasa Melayu | D5: Hai [达人昵称]! Saya suka sangat video anda tentang [视频内容]! 😊 Kedai baharu kami ada [品类] yang serupa — confirm sesuai dengan anda. Berminat untuk terima sampel percuma?
A6: 首次邀约·有礼版 | B6: WhatsApp | C6: English | D6: Hi, I'm [你的名字] from [店铺名]. We love your videos and would like to invite you to promote our products. If you're interested, please let me know. We'd like to offer you commission + product video materials. Look forward to hearing from you! 😊 | E6: 出自《达人合作邀请文案参考》马来部分，语气有礼，适合品牌店。
A7: 首次邀约·有礼版 | B7: WhatsApp | C7: Bahasa Melayu | D7: Hai, saya [你的名字] dari kedai [店铺名]. Kami sangat menyukai video anda dan ingin menjemput anda untuk mempromosikan produk kami. Jika anda berminat, sila beritahu saya. Kami ingin menawarkan anda komisen + bahan kandungan video produk. Berharap untuk mendengar daripada anda! 😊 | E7: 原文马来语版（直接可用）。
A8: 定向邀请(带卖点+利益点) | B8: WhatsApp | C8: English | D8: Hi [达人昵称] 🥰 We're [店铺名] and would love you to promote our [品类]. Key selling points: [卖点] — a great match for your followers! We offer [free sample 🎁 / [X]% commission / paid boost on top videos]. Contact us if you're interested — can't wait! 🤩 | E8: 掘金宝典定向邀请结构。
A9: 定向邀请(带卖点+利益点) | B9: WhatsApp | C9: Bahasa Melayu | D9: Hai [达人昵称] 🥰 Kami dari [店铺名], ingin menjemput anda mempromosikan [品类] kami. Kelebihan utama: [卖点] — sangat sepadan dengan peminat anda! Kami sediakan [sampel percuma 🎁 / komisen [X]% / sokongan iklan untuk video terbaik]. Hubungi kami kalau berminat — sangat dinantikan! 🤩
A10: 初次陌生触达·三段式框架 | B10: WhatsApp | C10: 框架/Framework | D10: ① 自我介绍+公司背书（例『我们是马来 TikTok Shop [类目] 卖家，已合作 [X] 位达人』🔥）→ ② 说明来意+提对方具体视频（『你的 [视频] 拿了 [赞数] 赞』）→ ③ 货盘优势+利益点（免费样品🎁 / [X]% 佣金 / 爆款脚本 / 投流 / 长期好货）。 | E10: 按此结构本地化成马来语再发。
A11: 引导多品一次申样 | B11: WhatsApp | C11: English | D11: Besides the [已申请商品] you requested, we also have [商品B] and [商品C] that would suit you — [卖点B] / [卖点C] 🤩. Tell me which ones interest you and we can send them together in one parcel to save time & shipping. | E11: 省运费：一次申请多件、一个包裹寄出。
A12: 引导多品一次申样 | B12: WhatsApp | C12: Bahasa Melayu | D12: Selain [已申请商品] yang anda mohon, kami ada [商品B] dan [商品C] yang sesuai juga — [卖点B] / [卖点C] 🤩. Beritahu saya yang mana anda minat, boleh kami hantar sekali dalam satu bungkusan untuk jimat masa & kos penghantaran.
A13: 样品寄出后 | B13: WhatsApp | C13: English | D13: Hi [达人昵称], your sample has been shipped 😄 Tracking no.: [物流单号]. Please check it's in good condition before filming, and tell me anytime if there's any issue. Looking forward to working with you! 🥰
A14: 样品寄出后 | B14: WhatsApp | C14: Bahasa Melayu | D14: Hai [达人昵称], sampel anda sudah dihantar 😄 No. penjejakan: [物流单号]. Sila periksa keadaannya sebelum merakam, dan beritahu saya bila-bila masa jika ada masalah. Tak sabar nak bekerjasama! 🥰
A15: 样品到货激励 | B15: WhatsApp | C15: English | D15: Hi [达人昵称], has the sample arrived? 🎁 Many creators earn [金额] commission from a single [品类] video — you can too! 👍 Here's a top-performing reference video: [视频链接]. When do you think you could post? | E15: 附本地播放量最高的同款视频 + 爆文脚本。
A16: 样品到货激励 | B16: WhatsApp | C16: Bahasa Melayu | D16: Hai [达人昵称], sampel dah sampai? 🎁 Ramai kreator dapat komisen [金额] daripada satu video [品类] sahaja — anda pun boleh! 👍 Ini video rujukan paling laris: [视频链接]. Agak-agak bila boleh post ya?
A17: 催未发文 | B17: WhatsApp | C17: English | D17: Hi [达人昵称], the sample arrived a few days ago but I haven't seen the video yet — any concerns? 🙌 When do you expect to post? We have a special [促销/流量扶持/库存紧张] offer right now, let's not miss it!
A18: 催未发文 | B18: WhatsApp | C18: Bahasa Melayu | D18: Hai [达人昵称], sampel dah sampai beberapa hari tapi video belum naik lagi — ada apa-apa masalah ke? 🙌 Jangkaan bila boleh post? Kami ada tawaran khas [促销/流量扶持/stok terhad] sekarang, jangan lepaskan peluang ya!
A19: 维护·内容差/没出单 | B19: WhatsApp | C19: English | D19: Hi [达人昵称], thanks for the video! 🙏 To get even better results, here's a proven script/example: [脚本链接]. Want to try another take? Happy to support you. | E19: 鼓励提质 + 给爆文脚本参考。
A20: 维护·内容差/没出单 | B20: WhatsApp | C20: Bahasa Melayu | D20: Hai [达人昵称], terima kasih atas video! 🙏 Untuk hasil lebih baik, ini skrip/contoh yang terbukti laris: [脚本链接]. Nak cuba sekali lagi? Saya sedia bantu.
A21: 维护·出单但只发一条 | B21: WhatsApp | C21: English | D21: Hi [达人昵称], your video did great! 🔥 Our top creators post [X] videos a week, reach [播放量] views and earn [佣金] — you have the same potential. Shall we line up the next one? | E21: 用 Top 达人数据激励多发。
A22: 维护·出单但只发一条 | B22: WhatsApp | C22: Bahasa Melayu | D22: Hai [达人昵称], video anda memang bagus! 🔥 Kreator terbaik kami post [X] video seminggu, capai [播放量] tontonan dan dapat [佣金] — anda pun ada potensi sama. Jom rancang video seterusnya?
A23: 维护·重点达人(S/A级) | B23: WhatsApp | C23: English | D23: Hi [达人昵称], thanks for the steady great content! 🌟 You're one of our key partners — I'll give you early access to new arrivals and our best commission. New drop coming: [新品]. Want first dibs + samples? | E23: 重点维护：预告上新、特殊节点人工告知、谈更高佣金/买断素材投流。
A24: 维护·重点达人(S/A级) | B24: WhatsApp | C24: Bahasa Melayu | D24: Hai [达人昵称], terima kasih kerana sentiasa hasilkan kandungan terbaik! 🌟 Anda antara rakan utama kami — saya akan beri akses awal produk baharu dan komisen terbaik. Ada produk baharu: [新品]. Nak jadi yang pertama + sampel?
A25: ⚠️ 风格提示 | B25: — | C25: 说明 | D25: 参考库另有 60 条『工厂直发/高佣』话术，营销味重、含直贴微信/+86，仅适合海量陌拜起量，不适合品牌店。优先用以上有礼版并本地化。群发邮件务必 BCC 密送；站内私信对不回复的达人最多触及 5 次，珍惜次数。 | E25: 出自《海外小店达人邀约话术》60 条，谨慎使用。

Sheet 客服FAQ+自动回复
A1: 客服 FAQ + 自动回复 · 中英(含马来)对照
A2: 覆盖：欢迎语 / 8 个订单状态自动回复 / 常见问题 / 时效红线。{大括号}=订单变量(订单编号/预计送达/详情页链接，顾客点卡片时自动替换)；[方括号]=你按品/店替换。⚠️ 所有时效/SLA/政策以官方后台当期为准并填核对日期。
A3: 分类 | B3: 触发 / 订单状态 | C3: 语言 | D3: 话术 / 规则 | E3: 备注
A4: 欢迎语/问候语 | B4: 进店欢迎(模板1) | C4: English | D4: Welcome to my shop! I hope you have a great journey here. Please feel free to contact us if you have any questions. 😊 | E4: 聊天机器人问候语。
A5: 欢迎语/问候语 | B5: 进店欢迎(模板1) | C5: Bahasa Melayu | D5: Selamat datang ke kedai kami! 😊 Semoga anda seronok membeli-belah. Jika ada sebarang pertanyaan, jangan segan untuk menghubungi kami.
A6: 欢迎语/问候语 | B6: 聊天问候语 | C6: English | D6: Thank you for getting in touch. How may I help you today? 😊 | E6: 问候语上限示例 600 字符。
A7: 欢迎语/问候语 | B7: 聊天问候语 | C7: Bahasa Melayu | D7: Terima kasih kerana menghubungi kami. Apa yang boleh saya bantu hari ini? 😊
A8: 欢迎语/问候语 | B8: 订单咨询问候 | C8: English | D8: Thanks for getting in touch! How may I help you with this order? 😊 | E8: 订单自动回复问候，上限示例 200 字符。
A9: 欢迎语/问候语 | B9: 订单咨询问候 | C9: Bahasa Melayu | D9: Terima kasih kerana menghubungi! Apa yang boleh saya bantu tentang pesanan ini? 😊
A10: 欢迎语/问候语 | B10: 品牌授权版(模板2·慎用) | C10: English | D10: Hi Dear, thanks for visiting my shop. This shop mainly sells [售卖商品]. We have brand authorization from [品牌方]. Wish you a good trip in our shop and please reach out whenever you need help. 😊 | E10: ⚠️ 仅在确有品牌授权时使用，否则按山寨处罚。
A11: 订单状态自动回复 | B11: 待支付 Unpaid | C11: English | D11: Hi, your order {订单编号} is awaiting payment. Tap here to complete it: {订单详情页链接}. Need help with payment methods? Just ask! 😊 | E11: 可插变量{订单编号}+链接。
A12: 订单状态自动回复 | B12: 待支付 Unpaid | C12: Bahasa Melayu | D12: Hai, pesanan anda {订单编号} masih menunggu pembayaran. Klik di sini untuk membayar: {订单详情页链接}. Perlukan bantuan tentang kaedah pembayaran? Tanya saja! 😊
A13: 订单状态自动回复 | B13: 待发货 To Ship | C13: English | D13: Hello, we're preparing your order {订单编号}. We normally ship within 72 hours from our China warehouse, then it takes about [X] days to arrive. Thanks for your patience! 😊 | E13: 时效以马来实际物流/官方为准；可嵌 {订单编号} 变量与订单/物流详情页链接。
A14: 订单状态自动回复 | B14: 待发货 To Ship | C14: Bahasa Melayu | D14: Hai, kami sedang menyediakan pesanan anda {订单编号}. Biasanya kami menghantar dalam masa 72 jam dari gudang China, kemudian mengambil masa kira-kira [X] hari untuk sampai. Terima kasih atas kesabaran anda! 😊 | E14: 时效以马来实际物流/官方为准；可嵌 {订单编号} 变量与订单/物流详情页链接。
A15: 订单状态自动回复 | B15: 等待收件 Awaiting Pickup | C15: English | D15: Hi, your order {订单编号} is packed and waiting for carrier pickup. We'll update the tracking as soon as it's collected. 😊
A16: 订单状态自动回复 | B16: 等待收件 Awaiting Pickup | C16: Bahasa Melayu | D16: Hai, pesanan anda {订单编号} sudah dibungkus dan menunggu kurier mengambilnya. Kami akan kemas kini penjejakan sebaik sahaja ia diambil. 😊
A17: 订单状态自动回复 | B17: 已发货 Shipped | C17: English | D17: Good news! Your order {订单编号} has shipped 🚚 Track it here: {物流详情页链接}. Estimated delivery: {预计送达}. Let us know if you have any questions! 😊 | E17: 时效以马来实际物流/官方为准；可嵌 {订单编号} 变量与订单/物流详情页链接。
A18: 订单状态自动回复 | B18: 已发货 Shipped | C18: Bahasa Melayu | D18: Berita baik! Pesanan anda {订单编号} telah dihantar 🚚 Jejaki di sini: {物流详情页链接}. Anggaran sampai: {预计送达}. Beritahu kami jika ada soalan! 😊 | E18: 时效以马来实际物流/官方为准；可嵌 {订单编号} 变量与订单/物流详情页链接。
A19: 订单状态自动回复 | B19: 已送达 Delivered | C19: English | D19: Hi, our records show your order {订单编号} has been delivered 📦 Hope you love it! If anything's not right, contact us within [X] days and we'll help. A review would mean a lot! ⭐
A20: 订单状态自动回复 | B20: 已送达 Delivered | C20: Bahasa Melayu | D20: Hai, rekod kami menunjukkan pesanan {订单编号} telah dihantar 📦 Harap anda sukakannya! Jika ada apa-apa masalah, hubungi kami dalam [X] hari dan kami akan bantu. Ulasan anda amat dihargai! ⭐
A21: 订单状态自动回复 | B21: 已完成 Completed | C21: English | D21: Thank you for shopping with us! 🥰 We hope you're happy with your purchase. If you have a moment, a 5-star review helps our small shop a lot. See you again! | E21: 可附小额优惠券激励好评+复购。
A22: 订单状态自动回复 | B22: 已完成 Completed | C22: Bahasa Melayu | D22: Terima kasih kerana membeli-belah dengan kami! 🥰 Harap anda berpuas hati. Jika ada masa, ulasan 5 bintang amat membantu kedai kecil kami. Jumpa lagi!
A23: 订单状态自动回复 | B23: 已取消 Cancelled | C23: English | D23: Hi, your order {订单编号} has been cancelled. If this was a mistake or you'd like to reorder, we're happy to help — just let us know! 😊
A24: 订单状态自动回复 | B24: 已取消 Cancelled | C24: Bahasa Melayu | D24: Hai, pesanan anda {订单编号} telah dibatalkan. Jika ini satu kesilapan atau anda ingin memesan semula, kami sedia membantu — beritahu kami sahaja! 😊
A25: 订单状态自动回复 | B25: 退货/退款 Return/Refund | C25: English | D25: We're sorry there's an issue with order {订单编号} 🙏 Could you share a photo/short video of the problem? We'll resolve it quickly — refund, replacement or partial refund, whichever you prefer. Your satisfaction matters to us. | E25: 先稳情绪→引导私信→给补偿方案。
A26: 订单状态自动回复 | B26: 退货/退款 Return/Refund | C26: Bahasa Melayu | D26: Kami minta maaf atas masalah dengan pesanan {订单编号} 🙏 Boleh anda kongsikan gambar/video pendek masalah itu? Kami akan selesaikan dengan cepat — bayaran balik, gantian atau bayaran balik separa, ikut pilihan anda. Kepuasan anda penting bagi kami.
A27: 常见问题 FAQ | B27: 物流时效 | C27: English | D27: Orders ship from our China warehouse, usually within 72 hours, and typically arrive in about [X] calendar days. You'll get a tracking number once shipped. 😊 | E27: 时效以马来实际物流/官方为准；可嵌 {订单编号} 变量与订单/物流详情页链接。
A28: 常见问题 FAQ | B28: 物流时效 | C28: Bahasa Melayu | D28: Pesanan dihantar dari gudang China kami, biasanya dalam 72 jam, dan kebiasaannya sampai dalam kira-kira [X] hari. Anda akan menerima nombor penjejakan selepas dihantar. 😊 | E28: 时效以马来实际物流/官方为准；可嵌 {订单编号} 变量与订单/物流详情页链接。
A29: 常见问题 FAQ | B29: 尺码 Size | C29: English | D29: Please check the size chart on the product page. If you tell me your height / weight / usual size, I'll recommend the best fit. 😊 | E29: 退货多因尺码→上架前写清尺码表。
A30: 常见问题 FAQ | B30: 尺码 Size | C30: Bahasa Melayu | D30: Sila rujuk carta saiz di halaman produk. Jika anda beritahu tinggi / berat / saiz biasa anda, saya boleh cadangkan saiz yang paling sesuai. 😊
A31: 常见问题 FAQ | B31: 材质 Material | C31: English | D31: The material is [材质], as listed in the product details. Please note colours may vary slightly due to lighting and screens. 😊
A32: 常见问题 FAQ | B32: 材质 Material | C32: Bahasa Melayu | D32: Bahannya ialah [材质], seperti tertera di butiran produk. Sila ambil maklum warna mungkin berbeza sedikit kerana pencahayaan dan skrin. 😊
A33: 常见问题 FAQ | B33: 退换货 Return/Exchange | C33: English | D33: Yes — if the item has a quality issue or doesn't match the description, contact us within [X] days with a photo/video and we'll arrange a return, exchange or refund. 🙏 | E33: 退换政策以官方+本店为准。
A34: 常见问题 FAQ | B34: 退换货 Return/Exchange | C34: Bahasa Melayu | D34: Boleh — jika produk ada masalah kualiti atau tidak sepadan dengan penerangan, hubungi kami dalam [X] hari dengan gambar/video dan kami akan uruskan pemulangan, pertukaran atau bayaran balik. 🙏
A35: 常见问题 FAQ | B35: 优惠券 Voucher | C35: English | D35: Let me check for you. 😊 We often have new-customer vouchers and bundle deals — tap 'Vouchers' on our shop page, or buy [X]+ to save more!
A36: 常见问题 FAQ | B36: 优惠券 Voucher | C36: Bahasa Melayu | D36: Biar saya semakkan untuk anda. 😊 Kami selalu ada baucar pelanggan baharu dan tawaran pakej — klik 'Baucar' di halaman kedai, atau beli [X]+ untuk jimat lebih!
A37: 常见问题 FAQ | B37: 赠品 Free gift | C37: English | D37: Let me look into this for you. 😊 | E37: 平台预设保通用性话术。
A38: 常见问题 FAQ | B38: 赠品 Free gift | C38: Bahasa Melayu | D38: Biar saya semak dahulu untuk anda. 😊
A39: 常见问题 FAQ | B39: 发票 Invoice | C39: English | D39: Platform invoices are issued by TikTok Shop. You can view/download them from your order or the Help Center. If you need shop details, let me know. 😊 | E39: 发票主体如 TikTok Shop (Malaysia) Sdn. Bhd.
A40: 常见问题 FAQ | B40: 发票 Invoice | C40: Bahasa Melayu | D40: Invois platform dikeluarkan oleh TikTok Shop. Anda boleh lihat/muat turun dari pesanan anda atau Pusat Bantuan. Jika perlukan butiran kedai, beritahu saya. 😊
...
